Workbook
Name ACTION: #REF!
Name ACTION: #REF!

Sheet Cover
B2: TEST REPORT DOCUMENT
A4: Project Name | B4: FoodFund | E4: Creator | F4: PhuocTM
A5: Project Code | B5: FA25SE52 | E5: Issue Date | F5: 30/10/2025
A6: Document Code | B6: =B5&"_"&"Test Report"&"_"&"v1.0" -> FA25SE52_Test Report_v1.0 | E6: Version | F6: 1.1
A9: Record of change
A10: Effective Date | B10: Version | C10: Change Item | D10: *A,D,M | E10: Change description | F10: Reference
A11: 25/11/2025 | B11: 1.0 | D11: A | E11: Add new test
A12: 30/11/2025 | B12: 1.1 | D12: A | E12: Add test case and function

Sheet Test Cases
D1: TEST CASE LIST
B3: Project Name | D3: FoodFund - A crowdfunding system for food preparation and distribution to support communities in need
B4: Project Code | D4: FA25SE52
B5: Test Environment Setup Description | D5: 1. FoodFund API Server 2. PostgreSQL Server Database 3. Google Chrome Web Browser
B8: No | C8: Function Name | D8: Sheet Name | E8: Description | F8: Pre-Condition
B9: 1 | C9: Signin | D9: Authentication
B10: 2 | C10: Signup | D10: Authentication
B11: 3 | C11: Forgot password | D11: Authentication
B12: 4 | C12: Change password | D12: Authentication
B13: 5 | C13: Request to create an organization | D13: Organization
B14: 6 | C14: View list active organizations | D14: Organization
B15: 7 | C15: View organization detail | D15: Organization
B16: 8 | C16: View join request organization | D16: Organization
B17: 9 | C17: View list organization creation requests | D17: Organization
B18: 10 | C18: View my organization | D18: Organization
B19: 11 | C19: Admin approves organization | D19: Organization
B20: 12 | C20: Admin rejects organization | D20: Organization
... B88: 80 | C88: Delete category | D88: CampaignCategory

Sheet Test Statistics
B1: TEST STATISTICS
B3: Project Name | C3: FoodFund - A crowdfunding system for food preparation and distribution to support communities in need | E3: Creator | H3: PhuocTM
B4: Project Code | C4: FA25SE52 | E4: Reviewer/Approver | H4: Nguyễn Minh Sang
B5: Document Code | C5: =C4&"_"&"Test Report"&"_"&"v1.1" -> FA25SE52_Test Report_v1.1 | E5: Issue Date | H5: 25/11/2025
B6: Notes
B10: No | C10: Module code | D10: Passed | E10: Failed | F10: Pending | G10: N/A | H10: Number of test cases
B11: 1 | C11: =Authentication!B2 -> Authentication | D11: =Authentication!B6 -> 15 | E11: =Authentication!C6 -> 0 | F11: =Authentication!D6 -> 0 | G11: =Authentication!E6 -> 0 | H11: =Authentication!B4 -> 15
B12: 2 | C12: =Organization!B2 -> Organization | D12: =Organization!B6 -> 10 | E12: =Organization!C6 -> 0 | F12: =Organization!D6 -> 0 | G12: =Organization!E6 -> 0 | H12: =Organization!B4 -> 10
B13: 3 | C13: =Donation!B2 -> Donation | D13: =Donation!B6 -> 12 | E13: =Donation!C6 -> 0 | F13: =Donation!D6 -> 0 | G13: =Donation!E6 -> 0 | H13: =Donation!B4 -> 12
B14: 4 | C14: =Wallet!B2 -> Wallet | D14: =Wallet!B6 -> 9 | E14: =Wallet!C6 -> 0 | F14: =Wallet!D6 -> 0 | G14: =Wallet!E6 -> 0 | H14: =Wallet!B4 -> 9
B15: 5 | C15: =IngredientRequest!B2 -> Ingredient Request | D15: =IngredientRequest!B6 -> 20 | E15: =IngredientRequest!C6 -> 0 | F15: =IngredientRequest!D6 -> 0 | G15: =IngredientRequest!E6 -> 0 | H15: =IngredientRequest!B4 -> 20
B16: 6 | C16: =OperationRequest!B2 -> Operation Request | D16: =OperationRequest!B6 -> 22 | E16: =OperationRequest!C6 -> 0 | F16: =OperationRequest!D6 -> 0 | G16: =OperationRequest!E6 -> 0 | H16: =OperationRequest!B4 -> 22
B17: 7 | C17: =MealBatchRequest!B2 -> Meal Batch Request | D17: =MealBatchRequest!B6 -> 20 | E17: =MealBatchRequest!C6 -> 0 | F17: =MealBatchRequest!D6 -> 0 | G17: =MealBatchRequest!E6 -> 0 | H17: =MealBatchRequest!B4 -> 20
B18: 8 | C18: =DeliveryTaskRequest!B2 -> Delivery Task Request | D18: =DeliveryTaskRequest!B6 -> 18 | E18: =DeliveryTaskRequest!C6 -> 0 | F18: =DeliveryTaskRequest!D6 -> 0 | G18: =DeliveryTaskRequest!E6 -> 0 | H18: =DeliveryTaskRequest!B4 -> 18
B19: 9 | C19: =InflowTransaction!B2 -> Inflow Transaction | D19: =InflowTransaction!B6 -> 10 | E19: =InflowTransaction!C6 -> 0 | F19: =InflowTransaction!D6 -> 0 | G19: =InflowTransaction!E6 -> 0 | H19: =InflowTransaction!B4 -> 10
B20: 10 | C20: =Campaign!B2 -> Campaign | D20: =Campaign!B6 -> 21 | E20: =Campaign!C6 -> 0 | F20: =Campaign!D6 -> 0 | G20: =Campaign!E6 -> 0 | H20: =Campaign!B4 -> 21
B21: 11 | C21: Notification | D21: =Notification!B6 -> 8 | E21: =Notification!C6 -> 0 | F21: =Notification!D6 -> 0 | G21: =Notification!E6 -> 0 | H21: =Notification!B4 -> 8
B22: 12 | C22: System Config | D22: =SystemConfig!B7 -> 6 | E22: =SystemConfig!C7 -> 0 | F22: =SystemConfig!D7 -> 0 | G22: =SystemConfig!E7 -> 0 | H22: =SystemConfig!B4 -> 6
B23: 13 | C23: Expense Proof | D23: =ExpenseProof!B7 -> 12 | E23: =ExpenseProof!C7 -> 0 | F23: =ExpenseProof!D7 -> 0 | G23: =ExpenseProof!E7 -> 0 | H23: =ExpenseProof!B4 -> 12
B24: 14 | C24: Profile | D24: =Profile!B7 -> 8 | E24: =Profile!C7 -> 0 | F24: =Profile!D7 -> 0 | G24: =Profile!E7 -> 0 | H24: =Profile!B4 -> 8
B25: 15 | C25: Campaign Category | D25: =CampaignCategory!B7 -> 9 | E25: =CampaignCategory!C7 -> 0 | F25: =CampaignCategory!D7 -> 0 | G25: =CampaignCategory!E7 -> 0 | H25: =CampaignCategory!B4 -> 9
C26: Sub total | D26: =SUM(D11:D25) -> 200 | E26: =SUM(E11:E25) -> 0 | F26: =SUM(F11:F25) -> 0 | G26: =SUM(G11:G25) -> 0 | H26: =SUM(H11:H25) -> 200
C28: Test coverage | E28: =(D26+E26)*100/(H26-G26) -> 100 | F28: %
C29: Test successful coverage | E29: =D26*100/(H26-G26) -> 100 | F29: %

Sheet Authentication
A2: Feature | B2: Authentication | R2: Passed
A3: Test requirement | R3: Failed
A4: Number of TCs | B4: =COUNTIF(A11:A319, "AU*") -> 15 | R4: Pending
A5: Testing Round | B5: Passed | C5: Failed | D5: Pending | E5: N/A | R5: N/A
A6: Round 1 | B6: =COUNTIF($F10:$F1007,B5) -> 15 | C6: =COUNTIF($F10:$F1007,C5) -> 0 | D6: =COUNTIF($F10:$F1007,D5) -> 0 | E6: =COUNTIF($F10:$F1007,E5) -> 0
A7: Round 2 | B7: =COUNTIF($F10:$F1007,B5) -> 15 | C7: =COUNTIF($F10:$F1007,C5) -> 0 | D7: =COUNTIF($F10:$F1007,D5) -> 0 | E7: =COUNTIF($F10:$F1007,E5) -> 0
A8: Round 3 | B8: =COUNTIF($F10:$F1007,B5) -> 15 | C8: =COUNTIF($F10:$F1007,C5) -> 0 | D8: =COUNTIF($F10:$F1007,D5) -> 0 | E8: =COUNTIF($F10:$F1007,E5) -> 0
A10: Test Case ID | B10: Test Case Description | C10: Test Case Procedure | D10: Expected Results | E10: Pre-conditions | F10: Round 1 | G10: Test date | H10: Tester | I10: Round 2 | J10: Test date | K10: Tester | L10: Round 3 | M10: Test date | N10: Tester | O10: Note
A11: Sign In
A12: AU1 | B12: Verify successful sign in with valid donor role credentials | C12: 1. Navigate to website: https://food-fund.vercel.app/login 2. Input form with values: - Email: phuoctmse184067@fpt.edu.vn - Mật khẩu: phuoc9111 3. Click button "Đăng nhập" | D12: - Sign in successfully. - Toast message: "Đăng nhập thành công" - Navigate to home screen. | E12: N/A | F12: Passed | G12: 25/11/2025 | H12: PhuocTM | I12: Passed | J12: 25/11/2025 | K12: HoangHLN | L12: Passed | M12: 25/11/2025 | N12: DuyPCB
A13: AU2 | B13: Verify successful sign in with valid fundraiser role credentials | C13: "1. Navigate to website: https://food-fund.vercel.app/login 2. Input form with values: - Email: hoanghlnse172474@fpt.edu.vn - Mật khẩu: 123456 3. Click button "Đăng nhập" | D13: - Sign in successfully. - Toast message: "Đăng nhập thành công" - Navigate to home screen. | E13: N/A | F13: Passed | G13: 25/11/2025 | H13: PhuocTM | I13: Passed | J13: 25/11/2025 | K13: HoangHLN | L13: Passed | M13: 25/11/2025 | N13: DuyPCB
A14: AU3 | B14: Verify successful sign in with valid kitchen staff role credentials | C14: "1. Navigate to website: https://food-fund.vercel.app/login 2. Input form with values: - Email: duypcbse184173@fpt.edu.vn - Mật khẩu: 123123 3. Click button "Đăng nhập" | D14: - Sign in successfully. - Toast message: "Đăng nhập thành công" - Navigate to home screen. | E14: N/A | F14: Passed | G14: 25/11/2025 | H14: PhuocTM | I14: Passed | J14: 25/11/2025 | K14: DuyPCB | L14: Passed | M14: 25/11/2025 | N14: LuyenHD
A15: AU4 | B15: Verify successful sign in with valid delivery staff role credentials | C15: "1. Navigate to website: https://food-fund.vercel.app/login 2. Input form with values: - Email: skyglaze911@gmail.com - Mật khẩu: 123123 3. Click button "Đăng nhập" | D15: - Sign in successfully. - Toast message: "Đăng nhập thành công" - Navigate to home screen. | E15: N/A | F15: Passed | G15: 25/11/2025 | H15: PhuocTM | I15: Passed | J15: 25/11/2025 | K15: DuyPCB | L15: Passed | M15: 25/11/2025 | N15: LuyenHD
A16: AU5 | B16: Verify successful sign in with valid admin role credentials | C16: "1. Navigate to website: https://food-fund.vercel.app/login 2. Input form with values: - Email: admin@gmail.com - Mật khẩu: foodfund 3. Click button "Đăng nhập" | D16: - Sign in successfully. - Toast message: "Đăng nhập thành công" - Navigate to home screen. | E16: N/A | F16: Passed | G16: 25/11/2025 | H16: PhuocTM | I16: Passed | J16: 25/11/2025 | K16: HoangHLN | L16: Passed | M16: 25/11/2025 | N16: LuyenHD
A17: AU6 | B17: Verify sign in with invalid email | C17: "1. Navigate to website: https://food-fund.vercel.app/login 2. Input form with values: - Email: rol1@gmail.com - Mật khẩu: password 3. Click button "Đăng nhập" | D17: - System shows toast error message: "Sai tài khoản hoặc mật khẩu" | E17: N/A | F17: Passed | G17: 25/11/2025 | H17: PhuocTM | I17: Passed | J17: 25/11/2025 | K17: HoangHLN | L17: Passed | M17: 25/11/2025 | N17: DuyPCB
A18: AU7 | B18: Verify sign in with invalid password | C18: 1. Navigate to website: https://food-fund.vercel.app/login 2. Input form with values: - Email: phuoc9111@gmail.com - Mật khẩu: password12 3. Click button "Đăng nhập" | D18: - System shows toast error message: "Sai tài khoản hoặc mật khẩu" | E18: N/A | F18: Passed | G18: 25/11/2025 | H18: PhuocTM | I18: Passed | J18: 25/11/2025 | K18: HoangHLN | L18: Passed | M18: 25/11/2025 | N18: DuyPCB
A19: AU8 | B19: Validate min length 6 characters of mật khẩu field | C19: 1. Navigate to website: https://food-fund.vercel.app/login 2. Click "Đăng kí ngay hôm nay" 2. Input form with values: - Họ và tên: Trương Minh Phước - Email: phuoctmse184067@fpt.edu.vn - Mật khẩu: pw - Xác nhận mật khẩu: pw 3. Click button "Đăng kí tài khoản" | D19: - System shows inline error message: "Mật khẩu phải có ít nhất 6 ký tự." | E19: N/A | F19: Passed | G19: 25/11/2025 | H19: PhuocTM | I19: Passed | J19: 25/11/2025 | K19: HoangHLN | L19: Passed | M19: 25/11/2025 | N19: DuyPCB
A20: AU9 | B20: Validate matching of xác nhận mật khẩu field | C20: 1. Navigate to website: https://food-fund.vercel.app/login 2. Click "Đăng kí ngay hôm nay" 2. Input form with values: - Họ và tên: Trương Minh Phước - Email: phuoctmse184067@fpt.edu.vn - Mật khẩu: 123123 - Xác nhận mật khẩu: pw 3. Click button "Đăng kí tài khoản" | D20: - System shows inline error message: "Mật khẩu xác nhận không khớp." | E20: N/A | F20: Passed | G20: 25/11/2025 | H20: PhuocTM | I20: Passed | J20: 25/11/2025 | K20: HoangHLN | L20: Passed | M20: 25/11/2025 | N20: DuyPCB
A21: AU10 | B21: Validate email type of email field | C21: 1. Navigate to website: https://food-fund.vercel.app/login 2. Click "Đăng kí ngay hôm nay" 2. Input form with values: - Họ và tên: Trương Minh Phước - Email: phuoctmse184067!fpt.edu.vn - Mật khẩu: 123123 - Xác nhận mật khẩu: 123123 3. Click button "Đăng kí tài khoản" | D21: - System shows error message in field: "Please provide an @ in email address." | E21: N/A | F21: Passed | G21: 25/11/2025 | H21: PhuocTM | I21: Passed | J21: 25/11/2025 | K21: HoangHLN | L21: Passed | M21: 25/11/2025 | N21: DuyPCB
A22: Sign Up
A23: AU11 | B23: Verify successful sign up | C23: 1. Navigate to website: https://food-fund.vercel.app/login 2. Click "Đăng kí ngay hôm nay" 2. Input form with values: - Họ và tên: Trương Minh Phước - Email: phuoctmse184067@fpt.edu.vn - Mật khẩu: 123123 - Xác nhận mật khẩu: 123123 3. Click button "Đăng kí tài khoản" | D23: - System navigate confirm sign up page - System send confirm sign up code via email | E23: N/A | F23: Passed | G23: 25/11/2025 | H23: PhuocTM | I23: Passed | J23: 25/11/2025 | K23: HoangHLN | L23: Passed | M23: 25/11/2025 | N23: DuyPCB
A24: AU12 | B24: Verify confirm sign up successfully | C24: 1. Input form with values: - Xác nhận mã đăng kí | D24: - System navigate to sign in page | E24: User must at sign up page before | F24: Passed | G24: 25/11/2025 | H24: PhuocTM | I24: Passed | J24: 25/11/2025 | K24: HoangHLN | L24: Passed | M24: 25/11/2025 | N24: DuyPCB
A25: Forgot Password
A26: AU13 | B26: Verify send forgot password code successfully | C26: 1. Navigate to website: https://food-fund.vercel.app/forgot-password 2. Input form with values: - Email: phuoc9111@gmail.com 3. Click "Gửi yêu cầu" | D26: - System shows toast success message: "Gửi OTP thành công" | E26: N/A | F26: Passed | G26: 25/11/2025 | H26: PhuocTM | I26: Passed | J26: 25/11/2025 | K26: HoangHLN | L26: Passed | M26: 25/11/2025 | N26: DuyPCB
A27: AU14 | B27: Validate email type of email field | C27: 1. Navigate to website: https://food-fund.vercel.app/forgot-password 2. Input form with values: - Email: phuoc9111@gmail.com 3. Click "Gửi yêu cầu" | D27: - System shows error message in field: "Please provide an @ in email address." | E27: N/A | F27: Passed | G27: 25/11/2025 | H27: PhuocTM | I27: Passed | J27: 25/11/2025 | K27: HoangHLN | L27: Passed | M27: 25/11/2025 | N27: DuyPCB
A28: Change Password
A29: AU15 | B29: Verify change password successfully | C29: 1. Input form with values: - Nhập mã OTP: 123456 - Mật khẩu mới: phuoc9123 - Nhập lại mật khẩu mới: phuoc9123 | D29: - System shows toast success message: "Thay đổi mật khẩu thành công" | E29: User must at forgot password screen | F29: Passed | G29: 25/11/2025 | H29: PhuocTM | I29: Passed | J29: 25/11/2025 | K29: HoangHLN | L29: Passed | M29: 25/11/2025 | N29: DuyPCB

Sheet Profile
A2: Feature | B2: Profile | R2: Passed
A3: Test requirement | B3: Test Profile | R3: Failed
A4: Number of TCs | B4: =COUNTIF(A:A, "PF*") -> 8 | R4: Pending
A5: Testing Round | B5: Passed | C5: Failed | D5: Pending | E5: N/A | R5: N/A
A6: Round 1 | B6: =COUNTIF($F10:$F995,B5) -> 8 | C6: =COUNTIF($F10:$F973,C5) -> 0 | D6: =COUNTIF($F10:$F973,D5) -> 0 | E6: =COUNTIF($F10:$F973,E5) -> 0
A7: Round 2 | B7: =COUNTIFS($L$10:$L977, "Passed", $B$10:$B977, "<>") -> 8 | C7: =COUNTIF($F10:$F973,C5) -> 0 | D7: =COUNTIF($F10:$F973,D5) -> 0 | E7: =COUNTIF($F10:$F973,E5) -> 0
A8: Round 3 | B8: =COUNTIFS($L$10:$L978, "Passed", $B$10:$B978, "<>") -> 8 | C8: =COUNTIF($F10:$F973,C5) -> 0 | D8: =COUNTIF($F10:$F973,D5) -> 0 | E8: =COUNTIF($F10:$F973,E5) -> 0
A10: Test Case ID | B10: Test Case Description | C10: Test Case Procedure | D10: Expected Results | E10: Pre-conditions | F10: Round 1 | G10: Test date | H10: Tester | I10: Round 2 | J10: Test date | K10: Tester | L10: Round 3 | M10: Test date | N10: Tester | O10: Note
A11: Profile
A12: PF01 | B12: View Profile Details | C12: 1. Navigate to /profile. 2. Observe "Hồ sơ cá nhân" tab. | D12: - Shows Name, Username, Phone, Email, Role, Address correctly. - Fields are read-only by default. | E12: User logged in. | F12: Passed | G12: 45669 | H12: PhuocTM | I12: Passed | J12: 45728 | K12: HoangHLN | L12: Passed | M12: 45728 | N12: DuyPCB
A13: PF02 | B13: Edit Profile Details | C13: 1. Click "Chỉnh sửa" button. 2. Edit Name, Phone, Bio, Address. 3. Click "Cập nhật". | D13: - Toast success message. - New details saved and displayed. - Redux/Header name updates if changed. | E13: N/A | F13: Passed | G13: 45669 | H13: PhuocTM | I13: Passed | J13: 45728 | K13: HoangHLN | L13: Passed | M13: 45728 | N13: DuyPCB
A14: PF03 | B14: Upload Avatar | C14: 1. Click "Chọn ảnh". 2. Upload valid image (JPG/PNG < 5MB). 3. Click "Cập nhật". | D14: - Preview updates immediately. - Avatar saved to S3 and profile updated on save. - Top sidebar avatar updates. | E14: Mode: Editing profile. | F14: Passed | G14: 45669 | H14: PhuocTM | I14: Passed | J14: 45728 | K14: HoangHLN | L14: Passed | M14: 45728 | N14: DuyPCB
A15: PF04 | B15: Remove Avatar | C15: 1. Enter Edit mode. 2. Hover avatar, click "X". 3. Click "Cập nhật". | D15: - Avatar reverts to default placeholder. - Change persists after reload. | E15: User has avatar. | F15: Passed | G15: 45669 | H15: PhuocTM | I15: Passed | J15: 45728 | K15: HoangHLN | L15: Passed | M15: 45728 | N15: DuyPCB
A16: PF05 | B16: View My Badges | C16: 1. Scroll to Badge section. 2. Click badge card. | D16: - Dialog opens showing badge details (Icon, Name, Desc). | E16: User has a Badge. | F16: Passed | G16: 45669 | H16: PhuocTM | I16: Passed | J16: 45728 | K16: HoangHLN | L16: Passed | M16: 45728 | N16: DuyPCB
A17: PF06 | B17: Invalid Phone Number | C17: 1. Enter phone: 123 or abc. 2. Save. | D17: - Field border turns red. - Error text: "Số điện thoại không hợp lệ". - Save blocked. | E17: Edit Mode | F17: Passed | G17: 45669 | H17: PhuocTM | I17: Passed | J17: 45728 | K17: HoangHLN | L17: Passed | M17: 45728 | N17: DuyPCB
A18: PF07 | B18: Required Fields check | C18: 1. Clear Name. 2. Save. | D18: - (If validation exists) Error on Name field. - (If backend handles) API error toast. | E18: Edit Mode | F18: Passed | G18: 45669 | H18: PhuocTM | I18: Passed | J18: 45728 | K18: HoangHLN | L18: Passed | M18: 45728 | N18: DuyPCB
A19: PF08 | B19: Avatar - File Too Large | C19: 1. Upload > 5MB image. | D19: - Toast Error: "Kích thước file không được vượt quá 5MB". | E19: Edit Mode | F19: Passed | G19: 45669 | H19: PhuocTM | I19: Passed | J19: 45728 | K19: HoangHLN | L19: Passed | M19: 45728 | N19: DuyPCB

Sheet Organization
A2: Feature | B2: Organization | R2: Passed
A3: Test requirement | B3: Test Organization | R3: Failed
A4: Number of TCs | B4: =COUNTIF(A11:A314, "OR*") -> 10 | R4: Pending
A5: Testing Round | B5: Passed | C5: Failed | D5: Pending | E5: N/A | R5: N/A
A6: Round 1 | B6: =COUNTIF($F10:$F997,B5) -> 10 | C6: =COUNTIF($F10:$F997,C5) -> 0 | D6: =COUNTIF($F10:$F997,D5) -> 0 | E6: =COUNTIF($F10:$F997,E5) -> 0
A7: Round 2 | B7: =COUNTIF($F10:$F997,B5) -> 10 | C7: =COUNTIF($F10:$F997,C5) -> 0 | D7: =COUNTIF($F10:$F997,D5) -> 0 | E7: =COUNTIF($F10:$F997,E5) -> 0
A8: Round 3 | B8: =COUNTIF($F10:$F997,B5) -> 10 | C8: =COUNTIF($F10:$F997,C5) -> 0 | D8: =COUNTIF($F10:$F997,D5) -> 0 | E8: =COUNTIF($F10:$F997,E5) -> 0
A10: Test Case ID | B10: Test Case Description | C10: Test Case Procedure | D10: Expected Results | E10: Pre-conditions | F10: Round 1 | G10: Test date | H10: Tester | I10: Round 2 | J10: Test date | K10: Tester | L10: Round 3 | M10: Test date | N10: Tester | O10: Note
A11: Register Organization Request
A12: OR1 | B12: Verify donor send request register successfully with all valid input | C12: 1. Navigate to website: https://food-fund.vercel.app/register/organization 2. Fill in all mandatory fields with valid data 3. Click the "Đăng kí Tài Khoản Tổ chức" button. | D12: - The system successfully processes the registration details | E12: N/A | F12: Passed | G12: 25/11/2025 | H12: PhuocTM | I12: Passed | J12: 25/11/2025 | K12: HoangHLN | L12: Passed | M12: 25/11/2025 | N12: DuyPCB
A13: OR2 | B13: Verify banking information | C13: 1. Navigate to website: https://food-fund.vercel.app/register/organization 2. Fill in all mandatory fields with valid data 3. Click the "Check" button. | D13: -The system successfully show banking infomation | E13: N/A | F13: Passed | G13: 25/11/2025 | H13: PhuocTM | I13: Passed | J13: 25/11/2025 | K13: HoangHLN | L13: Passed | M13: 25/11/2025 | N13: DuyPCB
A14: OR3 | B14: Verify identity information | C14: 1. Navigate to website: https://food-fund.vercel.app/register/organization 2. Click "Tải ảnh CCCD/CMND để tự động điền thông tin" 3. Upload identity information front picture | D14: -The system successfully show identity infomation | E14: N/A | F14: Passed | G14: 25/11/2025 | H14: PhuocTM | I14: Passed | J14: 25/11/2025 | K14: HoangHLN | L14: Passed | M14: 25/11/2025 | N14: DuyPCB
A15: OR4 | B15: Validation required fields of register form | C15: 1. Leave all required fields empty: - Tên tổ chức - Lĩnh vực hoạt động - Số điện thoại - Email đại diện - Mô tả tổ chức - Số tài khoản - Mã ngân hàng - Tên ngân hàng 2. Attempt to submit the form (click "Đăng ký Tài Khoản Tổ chức"). | D15: - System shows error messages for each empty required field: + "Vui lòng nhập tên tổ chức." + "Vui lòng nhập lĩnh vực hoạt động." + "Vui lòng nhập số điện thoại." + "Vui lòng nhập email đại diện." + "Vui lòng nhập mô tả tổ chức." + "Vui lòng nhập số tài khoản." + "Vui lòng nhập mã ngân hàng." + "Vui lòng nhập tên ngân hàng." + "Vui lòng nhập tên chủ tài khoản." | E15: N/A | F15: Passed | G15: 25/11/2025 | H15: PhuocTM | I15: Passed | J15: 25/11/2025 | K15: HoangHLN | L15: Passed | M15: 25/11/2025 | N15: DuyPCB
A16: OR5 | B16: Validate input of "Email đại diện" field | C16: 1. Navigate to website: https://food-fund.vercel.app/register/organization 2. Input value: - Email đại diện | D16: - System shows error with message: "Email đại diện không hợp lệ." | E16: N/A | F16: Passed | G16: 25/11/2025 | H16: PhuocTM | I16: Passed | J16: 25/11/2025 | K16: HoangHLN | L16: Passed | M16: 25/11/2025 | N16: DuyPCB
A17: OR6 | B17: Validate input of "Số điện thoại" field | C17: 1. Navigate to website: https://food-fund.vercel.app/register/organization 2. Input value: - Số điện thoại | D17: - System shows error with message: "Số điện thoại không hợp lệ. Vui lòng nhập số điện thoại Việt Nam (+84 theo sau 9 chữ số)." | E17: N/A | F17: Passed | G17: 25/11/2025 | H17: PhuocTM | I17: Passed | J17: 25/11/2025 | K17: HoangHLN | L17: Passed | M17: 25/11/2025 | N17: DuyPCB
A18: OR7 | B18: Validate input of "Website" field | C18: 1. Navigate to website: https://food-fund.vercel.app/register/organization 2. Input require field and website value: - Tên tổ chức: "Tổ chức thiện nguyện quận 6" - Lĩnh vực hoạt động: "Thiện Nguyện" - Số điện thoại: "+84901038975" - Email đại diện: "thiennguyenquan6@gmail.com" - Mô tả tổ chức: "Tổ chức đi thiện nguyện" - Số tài khoản: "11111111111111" - Mã ngân hàng: VCB - Tên ngân hàng: "Ngân hàng TMCP Ngoại thương Việt Nam" - Website: "không-phải-url" | D18: - System shows error with message: "Website phải là dạng URL." | E18: N/A | F18: Passed | G18: 25/11/2025 | H18: PhuocTM | I18: Passed | J18: 25/11/2025 | K18: HoangHLN | L18: Passed | M18: 25/11/2025 | N18: DuyPCB
A19: Process Organization Creation Request
A20: OR8 | B20: Verify admin reject organization creation request successfully | C20: 1. Navigate to page: https://food-fund.vercel.app/admin/organization-requests 2. Choose PENDING organization menu button 3. Click menu button 4. Click "Từ chối" | D20: - The system successfully show toast message "Đã từ chối yêu cầu tạo tổ chức" | E20: N/A | F20: Passed | G20: 25/11/2025 | H20: PhuocTM | I20: Passed | J20: 25/11/2025 | K20: HoangHLN | L20: Passed | M20: 25/11/2025 | N20: DuyPCB
A21: OR9 | B21: Verify admin approve organization creation request successfully | C21: 1. Navigate to page: https://food-fund.vercel.app/admin/organization-requests 2. Choose PENDING organization menu button 3. Click menu button 4. Click "Phê duyệt" | D21: - The system successfully show toast message "Yêu cầu tạo tổ chức được phê duyệt thành công" | E21: N/A | F21: Passed | G21: 25/11/2025 | H21: PhuocTM | I21: Passed | J21: 25/11/2025 | K21: HoangHLN | L21: Passed | M21: 25/11/2025 | N21: DuyPCB
A22: Leave Organization
A23: OR10 | B23: Verify staff leave organization | C23: 1. Navigate to page: https://food-fund.vercel.app/profile?tab=join_requests 2. Click "Rời tổ chức" | D23: - The system successfully show toast message "Rời tổ chức thành công" | E23: Staff must be signin | F23: Passed | G23: 25/11/2025 | H23: PhuocTM | I23: Passed | J23: 25/11/2025 | K23: HoangHLN | L23: Passed | M23: 25/11/2025 | N23: DuyPCB

Sheet Donation
A2: Feature | B2: Donation | R2: Passed
A3: Test requirement | B3: Test Donation | R3: Failed
A4: Number of TCs | B4: =COUNTIF(A11:A315, "DO*") -> 12 | R4: Pending
A5: Testing Round | B5: Passed | C5: Failed | D5: Pending | E5: N/A | R5: N/A
A6: Round 1 | B6: =COUNTIF($F10:$F999,B5) -> 12 | C6: =COUNTIF($F10:$F999,C5) -> 0 | D6: =COUNTIF($F10:$F999,D5) -> 0 | E6: =COUNTIF($F10:$F999,E5) -> 0
A7: Round 2 | B7: =COUNTIF($F10:$F999,B5) -> 12 | C7: =COUNTIF($F10:$F999,C5) -> 0 | D7: =COUNTIF($F10:$F999,D5) -> 0 | E7: =COUNTIF($F10:$F999,E5) -> 0
A8: Round 3 | B8: =COUNTIF($F10:$F999,B5) -> 12 | C8: =COUNTIF($F10:$F999,C5) -> 0 | D8: =COUNTIF($F10:$F999,D5) -> 0 | E8: =COUNTIF($F10:$F999,E5) -> 0
A10: Test Case ID | B10: Test Case Description | C10: Test Case Procedure | D10: Expected Results | E10: Pre-conditions | F10: Round 1 | G10: Test date | H10: Tester | I10: Round 2 | J10: Test date | K10: Tester | L10: Round 3 | M10: Test date | N10: Tester | O10: Note
A11: Create Donation
A12: DO1 | B12: Verify donor create donation successfully | C12: 1. Navigate to choose campaign category: https://food-fund.vercel.app/discovery 2. Choose one campaign 3. Click "Ủng hộ" button 4. Click "Đồng ý và tiếp tục" 5. Enter an amount to donate 6. Click "Ủng hộ" button | D12: - The system show the transfer donation information (qr code, bank account, bank number, amount) | E12: N/A | F12: Passed | G12: 25/11/2025 | H12: PhuocTM | I12: Passed | J12: 25/11/2025 | K12: HoangHLN | L12: Passed | M12: 25/11/2025 | N12: DuyPCB
A13: DO2 | B13: Verify unauthenticated donor transfer successfully | C13: 1. Navigate to choose campaign category: https://food-fund.vercel.app/discovery 2. Choose one campaign 3. Click "Ủng hộ" tablist | D13: - The system show the donation with information(donor name, amount, transfer date) | E13: N/A | F13: Passed | G13: 25/11/2025 | H13: PhuocTM | I13: Passed | J13: 25/11/2025 | K13: HoangHLN | L13: Passed | M13: 25/11/2025 | N13: DuyPCB
A14: DO3 | B14: Verify authenticated donor transfer successfully | C14: 1. Navigate to choose campaign category: https://food-fund.vercel.app/discovery 2. Choose one campaign 3. Click "Ủng hộ" tablist | D14: - The system show the donation with information(donor name, amount, transfer date) - The system send an email with thank you letter to donor's registered email | E14: N/A | F14: Passed | G14: 25/11/2025 | H14: PhuocTM | I14: Passed | J14: 25/11/2025 | K14: HoangHLN | L14: Passed | M14: 25/11/2025 | N14: DuyPCB
A15: DO4 | B15: Validate input of "Nhập số tiền ủng hộ" field | C15: 1. Navigate to choose campaign category: https://food-fund.vercel.app/discovery 2. Choose one campaign 3. Click "Ủng hộ" button 4. Click "Đồng ý và tiếp tục" 5. Enter an amount to donate: - Số tiền ủng hộ | D15: - The system not show the amount of "Số tiền ủng hộ" | E15: N/A | F15: Passed | G15: 25/11/2025 | H15: PhuocTM | I15: Passed | J15: 25/11/2025 | K15: HoangHLN | L15: Passed | M15: 25/11/2025 | N15: DuyPCB
A16: DO5 | B16: Validate input of "Tên huy hiệu" field | C16: 1. Navigate to https://food-fund.vercel.app/admin/badges 2. Click "Chỉnh sửa" 3. Leave field "Tên huy hiệu" empty 4. Click "Chỉnh sửa" | D16: - The system show error toast "Tên huy hiệu không được để trống" | E16: N/A | F16: Passed | G16: 25/11/2025 | H16: PhuocTM | I16: Passed | J16: 25/11/2025 | K16: HoangHLN | L16: Passed | M16: 25/11/2025 | N16: DuyPCB
A17: DO6 | B17: Validate input of "Mô tả" field | C17: 1. Navigate to https://food-fund.vercel.app/admin/badges 2. Click "Chỉnh sửa" 3. Leave field "Mô tả" empty 4. Click "Chỉnh sửa" | D17: - The system show error toast "Mô tả không được để trống" | E17: N/A | F17: Passed | G17: 25/11/2025 | H17: PhuocTM | I17: Passed | J17: 25/11/2025 | K17: HoangHLN | L17: Passed | M17: 25/11/2025 | N17: DuyPCB
A18: DO7 | B18: Validate input of "Số thứ tự" field | C18: 1. Navigate to https://food-fund.vercel.app/admin/badges 2. Click "Chỉnh sửa" 3. Enter number 1 at "Số thứ tự" 4. Click "Chỉnh sửa" | D18: - The system show error toast "Số thứ tự đã có sẵn" | E18: N/A | F18: Passed | G18: 25/11/2025 | H18: PhuocTM | I18: Passed | J18: 25/11/2025 | K18: HoangHLN | L18: Passed | M18: 25/11/2025 | N18: DuyPCB
A19: Search Donation
A20: DO8 | B20: Search donotion transfer successfully | C20: 1. Navigate to choose campaign category: https://food-fund.vercel.app/discovery 2. Choose one campaign 3. Click "Ủng hộ" tablist 4. Input donor name or sorting | D20: - The system show the match information search donation | E20: N/A | F20: Passed | G20: 25/11/2025 | H20: PhuocTM | I20: Passed | J20: 25/11/2025 | K20: HoangHLN | L20: Passed | M20: 25/11/2025 | N20: DuyPCB
A21: Badge
A22: DO9 | B22: Award first time donation badge for donor | C22: 1. Navigate to choose campaign category: https://food-fund.vercel.app/discovery 2. Choose one campaign 3. Click "Ủng hộ" button 4. Click "Đồng ý và tiếp tục" 5. Enter an amount to donate 6. Click "Ủng hộ" button | D22: - The system send an email with system badge and milestone to upgrade badge | E22: - Donor must sign in - Donor has not been donated any campaigns before | F22: Passed | G22: 25/11/2025 | H22: PhuocTM | I22: Passed | J22: 25/11/2025 | K22: HoangHLN | L22: Passed | M22: 25/11/2025 | N22: DuyPCB
A23: DO10 | B23: Upgrade badge for donor | C23: 1. Navigate to choose campaign category: https://food-fund.vercel.app/discovery 2. Choose one campaign 3. Click "Ủng hộ" button 4. Click "Đồng ý và tiếp tục" 5. Enter an amount to donate 6. Click "Ủng hộ" button | D23: - The system send an email with system badge and milestone to upgrade badge | E23: - Donor must sign in - Donor has been donated campaigns before | F23: Passed | G23: 25/11/2025 | H23: PhuocTM | I23: Passed | J23: 25/11/2025 | K23: HoangHLN | L23: Passed | M23: 25/11/2025 | N23: DuyPCB
A24: DO11 | B24: Verify donor received badge successfully | C24: 1. Navigate to donor profile: https://food-fund.vercel.app/profile?tab=profile | D24: - The system show the information of badge | E24: - Donor must sign in | F24: Passed | G24: 25/11/2025 | H24: PhuocTM | I24: Passed | J24: 25/11/2025 | K24: HoangHLN | L24: Passed | M24: 25/11/2025 | N24: DuyPCB
A25: DO12 | B25: Verify admin update badge successfully | C25: 1. Navigate to https://food-fund.vercel.app/admin/badges 2. Click "Chỉnh sửa" | D25: - The system display success toast "Cập nhật huy hiệu thành công" | E25: Admin must be signed in | F25: Passed | G25: 25/11/2025 | H25: PhuocTM | I25: Passed | J25: 25/11/2025 | K25: HoangHLN | L25: Passed | M25: 25/11/2025 | N25: DuyPCB

Sheet Wallet
A2: Feature | B2: Wallet | R2: Passed
A3: Test requirement | B3: Test Wallet | R3: Failed
A4: Number of TCs | B4: =COUNTIF(A11:A314, "WA*") -> 9 | R4: Pending
A5: Testing Round | B5: Passed | C5: Failed | D5: Pending | E5: N/A | R5: N/A
A6: Round 1 | B6: =COUNTIF($F10:$F994,B5) -> 9 | C6: =COUNTIF($F10:$F994,C5) -> 0 | D6: =COUNTIF($F10:$F994,D5) -> 0 | E6: =COUNTIF($F10:$F994,E5) -> 0
A7: Round 2 | B7: =COUNTIF($F10:$F994,B5) -> 9 | C7: =COUNTIF($F10:$F994,C5) -> 0 | D7: =COUNTIF($F10:$F994,D5) -> 0 | E7: =COUNTIF($F10:$F994,E5) -> 0
A8: Round 3 | B8: =COUNTIF($F10:$F994,B5) -> 9 | C8: =COUNTIF($F10:$F994,C5) -> 0 | D8: =COUNTIF($F10:$F994,D5) -> 0 | E8: =COUNTIF($F10:$F994,E5) -> 0
A10: Test Case ID | B10: Test Case Description | C10: Test Case Procedure | D10: Expected Results | E10: Pre-conditions | F10: Round 1 | G10: Test date | H10: Tester | I10: Round 2 | J10: Test date | K10: Tester | L10: Round 3 | M10: Test date | N10: Tester | O10: Note
A11: Transaction Wallet
A12: WA1 | B12: Verify system store system wallet transactions successfully | C12: 1. Navigate to website: https://food-fund.vercel.app/ 2. Scroll down at title "Những con số biết nói" 3. Click "Xem chi tiết giao dịch hệ thống" | D12: - The system show the latest transaction | E12: Donor must donate first | F12: Passed | G12: 26/11/2025 | H12: PhuocTM | I12: Passed | J12: 26/11/2025 | K12: HoangHLN | L12: Passed | M12: 26/11/2025 | N12: DuyPCB
A13: WA2 | B13: Verify system synchronize balance and total income | C13: 1. Navigate to website: https://food-fund.vercel.app/ 2. Scroll down at title "Những con số biết nói" 3. Click "Xem chi tiết giao dịch hệ thống" | D13: - The system show the latest transaction with the information (Số dư trước, số dư sau) | E13: Donor must donate first | F13: Passed | G13: 26/11/2025 | H13: PhuocTM | I13: Passed | J13: 26/11/2025 | K13: HoangHLN | L13: Passed | M13: 26/11/2025 | N13: DuyPCB
A14: WA3 | B14: Verify system synchronize balance and total expense | C14: 1. Navigate to website: https://food-fund.vercel.app/ 2. Scroll down at title "Những con số biết nói" 3. Click "Xem chi tiết giao dịch hệ thống" | D14: - The system show the latest transaction with the information (Số dư trước, số dư sau) | E14: Admin must withdraw first | F14: Passed | G14: 26/11/2025 | H14: PhuocTM | I14: Passed | J14: 26/11/2025 | K14: HoangHLN | L14: Passed | M14: 26/11/2025 | N14: DuyPCB
A15: WA4 | B15: Verify sytem download Fundraiser wallet statement successfully | C15: 1. Navigate to website: https://food-fund.vercel.app/ 2. Choose one campaign category 3. Choose one campaign 4. Click "Xem sao kê tài khoản" button 5. Click "Xuất sao kê" button | D15: - The system successfully download file excel | E15: N/A | F15: Passed | G15: 26/11/2025 | H15: PhuocTM | I15: Passed | J15: 26/11/2025 | K15: HoangHLN | L15: Passed | M15: 26/11/2025 | N15: DuyPCB
A16: WA5 | B16: Search payment system wallet transaction successfully | C16: 1. Navigate to website: https://food-fund.vercel.app/ 2. Choose one campaign category 3. Choose one campaign 4. Click "Xem sao kê tài khoản" button 5. Input in search and sort field | D16: - The system successfully show the result matching with search input | E16: N/A | F16: Passed | G16: 26/11/2025 | H16: PhuocTM | I16: Passed | J16: 26/11/2025 | K16: HoangHLN | L16: Passed | M16: 26/11/2025 | N16: DuyPCB
A17: WA6 | B17: Negative Amount Input | C17: 1. Open Withdrawal/Filter form. 2. Enter amount: -100000. | D17: - The system successfully show the result matching with search input | E17: N/A | F17: Passed | G17: 26/11/2025 | H17: PhuocTM | I17: Passed | J17: 26/11/2025 | K17: HoangHLN | L17: Passed | M17: 26/11/2025 | N17: DuyPCB
A18: WA7 | B18: Zero Amount Input | C18: 1. Open Withdrawal form. 2. Enter amount: 0. | D18: - Validation error: "Số tiền phải lớn hơn 0". | E18: N/A | F18: Passed | G18: 26/11/2025 | H18: PhuocTM | I18: Passed | J18: 26/11/2025 | K18: HoangHLN | L18: Passed | M18: 26/11/2025 | N18: DuyPCB
A19: WA8 | B19: Invalid Date Range Filter | C19: 1. Open Date Filter. 2. Set From Date = 01/01/2025. 3. Set To Date = 01/01/2024 (Before From Date). | D19: - Validation error: "Ngày kết thúc phải sau ngày bắt đầu". - OR Auto-swap dates. - Search button disabled. | E19: Transactions exist. | F19: Passed | G19: 26/11/2025 | H19: PhuocTM | I19: Passed | J19: 26/11/2025 | K19: HoangHLN | L19: Passed | M19: 26/11/2025 | N19: DuyPCB
A20: WA9 | B20: Decimal Amount Handling | C20: 1. Enter amount with decimals: 50.5. | D20: - If VND supports integers only: Error "Vui lòng nhập số nguyên". - If supported: Accepted correctly. | E20: N/A | F20: Passed | G20: 26/11/2025 | H20: PhuocTM | I20: Passed | J20: 26/11/2025 | K20: HoangHLN | L20: Passed | M20: 26/11/2025 | N20: DuyPCB

Sheet IngredientRequest
A2: Feature | B2: Ingredient Request | R2: Passed
A3: Test requirement | B3: Test Ingredient Request | R3: Failed
A4: Number of TCs | B4: =COUNTIF(A11:A317, "IN*") -> 20 | R4: Pending
A5: Testing Round | B5: Passed | C5: Failed | D5: Pending | E5: N/A | R5: N/A
A6: Round 1 | B6: =COUNTIF($F10:$F997,B5) -> 20 | C6: =COUNTIF($F10:$F997,C5) -> 0 | D6: =COUNTIF($F10:$F997,D5) -> 0 | E6: =COUNTIF($F10:$F997,E5) -> 0
A7: Round 2 | B7: =COUNTIF($F10:$F997,B5) -> 20 | C7: =COUNTIF($F11:$F998,C6) -> 0 | D7: =COUNTIF($F10:$F997,D5) -> 0 | E7: =COUNTIF($F10:$F997,E5) -> 0
A8: Round 3 | B8: =COUNTIF($F10:$F997,B5) -> 20 | C8: =COUNTIF($F10:$F997,C5) -> 0 | D8: =COUNTIF($F10:$F997,D5) -> 0 | E8: =COUNTIF($F10:$F997,E5) -> 0
A10: Test Case ID | B10: Test Case Description | C10: Test Case Procedure | D10: Expected Results | E10: Pre-conditions | F10: Round 1 | G10: Test date | H10: Tester | I10: Round 2 | J10: Test date | K10: Tester | L10: Round 3 | M10: Test date | N10: Tester | O10: Note
A11: Request List Management
A12: IN01 | B12: Verify request list page UI display | C12: 1. Navigate to the ingredient request list page | D12: Page displays title "Yêu cầu nguyên liệu", "Quay lại" button, status filter chips, and "Tạo yêu cầu nguyên liệu mới" button | E12: User is logged in as Kitchen Staff | F12: Passed | G12: 26/11/2025 | H12: PhuocTM | I12: Passed | J12: 26/11/2025 | K12: HoangHLN | L12: Passed | M12: 26/11/2025 | N12: DuyPCB
A13: IN02 | B13: Verify request card data integrity | C13: 1. View existing request cards in the list | D13: Each card shows short code (e.g., "Yêu cầu #..."), created date, colored status chip, "Tổng chi phí dự kiến", and ingredient summary | E13: At least one request exists | F13: Passed | G13: 26/11/2025 | H13: PhuocTM | I13: Passed | J13: 26/11/2025 | K13: HoangHLN | L13: Passed | M13: 26/11/2025 | N13: DuyPCB
A14: IN03 | B14: Verify empty state display | C14: 1. Open the list page when no data is available | D14: Displays heart icon (♡), "Bạn chưa có yêu cầu nguyên liệu nào" message, and "Tạo yêu cầu nguyên liệu" button | E14: No requests exist for the phase | F14: Passed | G14: 26/11/2025 | H14: PhuocTM | I14: Passed | J14: 26/11/2025 | K14: HoangHLN | L14: Passed | M14: 26/11/2025 | N14: DuyPCB
A15: IN04 | B15: Verify card navigation | C15: 1. Tap on any request card | D15: System navigates user to the expense proof page with corresponding details | E15: At least one request exists | F15: Passed | G15: 26/11/2025 | H15: PhuocTM | I15: Passed | J15: 26/11/2025 | K15: HoangHLN | L15: Passed | M15: 26/11/2025 | N15: DuyPCB
A16: Filter & Sort Functions
A17: IN05 | B17: Filter by "Chờ duyệt" status | C17: 1. Tap the "Chờ duyệt" filter chip | D17: Only requests with PENDING status are displayed; the chip shows active styling | E17: Multiple requests with different statuses exist | F17: Passed | G17: 26/11/2025 | H17: PhuocTM | I17: Passed | J17: 26/11/2025 | K17: HoangHLN | L17: Passed | M17: 26/11/2025 | N17: DuyPCB
A18: IN06 | B18: Filter by "Đã duyệt" status | C18: 1. Tap the "Đã duyệt" filter chip | D18: Only requests with ACCEPTED status are displayed | E18: Multiple requests with different statuses exist | F18: Passed | G18: 26/11/2025 | H18: PhuocTM | I18: Passed | J18: 26/11/2025 | K18: HoangHLN | L18: Passed | M18: 26/11/2025 | N18: DuyPCB
A19: IN07 | B19: Filter by "Từ chối" status | C19: 1. Tap the "Từ chối" filter chip | D19: Only requests with REJECTED status are displayed | E19: Multiple requests with different statuses exist | F19: Passed | G19: 26/11/2025 | H19: PhuocTM | I19: Passed | J19: 26/11/2025 | K19: HoangHLN | L19: Passed | M19: 26/11/2025 | N19: DuyPCB
A20: IN08 | B20: Sort by newest/oldest | C20: 1. Select "Mới nhất" or "Cũ nhất" sort option | D20: Requests are sorted correctly by creation date (descending for "Mới nhất", ascending for "Cũ nhất") | E20: Multiple requests with different dates exist | F20: Passed | G20: 26/11/2025 | H20: PhuocTM | I20: Passed | J20: 26/11/2025 | K20: HoangHLN | L20: Passed | M20: 26/11/2025 | N20: DuyPCB
A21: Phase Selection Logic
A22: IN09 | B22: Verify budget info display by phase | C22: 1. Select a phase with an assigned budget | D22: The "Ngân sách nguyên liệu giai đoạn" box correctly updates to the selected phase's budget amount | E22: Selected phase has a budget > 0 | F22: Passed | G22: 26/11/2025 | H22: PhuocTM | I22: Passed | J22: 26/11/2025 | K22: HoangHLN | L22: Passed | M22: 26/11/2025 | N22: DuyPCB
A23: IN10 | B23: Verify auto-fill from plan | C23: 1. Select a phase containing planned ingredients | D23: Ingredient items are automatically generated with the "Từ kế hoạch" badge | E23: Phase has plannedIngredients data | F23: Passed | G23: 26/11/2025 | H23: PhuocTM | I23: Passed | J23: 26/11/2025 | K23: HoangHLN | L23: Passed | M23: 26/11/2025 | N23: DuyPCB
A24: IN11 | B24: Verify phase change updates items | C24: 1. Switch from one phase to another | D24: The existing item list is cleared and replaced by the new phase's planned ingredients | E24: Multiple phases with different plans exist | F24: Passed | G24: 26/11/2025 | H24: PhuocTM | I24: Passed | J24: 26/11/2025 | K24: HoangHLN | L24: Passed | M24: 26/11/2025 | N24: DuyPCB
A25: Item Ingredient Management
A26: IN12 | B26: Manually add new ingredient item | C26: 1. Tap "+ Thêm nguyên liệu mới" | D26: A new blank ingredient block is added to the list with default unit set to "kg" | E26: User is on the form page | F26: Passed | G26: 26/11/2025 | H26: PhuocTM | I26: Passed | J26: 26/11/2025 | K26: HoangHLN | L26: Passed | M26: 26/11/2025 | N26: DuyPCB
A27: IN13 | B27: Remove ingredient item | C27: 1. Tap the "Xóa" button on an item | D27: Item is removed from the list; the total cost in the summary bar recalculates instantly | E27: At least 2 items exist in the list | F27: Passed | G27: 26/11/2025 | H27: PhuocTM | I27: Passed | J27: 26/11/2025 | K27: HoangHLN | L27: Passed | M27: 26/11/2025 | N27: DuyPCB
A28: IN14 | B28: Unit selection via Modal | C28: 1. Tap the unit dropdown. 2. Select a unit (e.g., "lít") | D28: The "Chọn đơn vị" modal displays all 5 groups; selected unit updates on the field and modal closes | E28: User is on the form page | F28: Passed | G28: 26/11/2025 | H28: PhuocTM | I28: Passed | J28: 26/11/2025 | K28: HoangHLN | L28: Passed | M28: 26/11/2025 | N28: DuyPCB
A29: IN15 | B29: Auto-calculation of item total | C29: 1. Enter "Số lượng" (e.g., 5). 2. Enter "Đơn giá ước tính" (e.g., 10000) | D29: "Thành tiền ước tính" automatically updates to show "50,000" | E29: Quantity and unit price are valid numbers | F29: Passed | G29: 26/11/2025 | H29: PhuocTM | I29: Passed | J29: 26/11/2025 | K29: HoangHLN | L29: Passed | M29: 26/11/2025 | N29: DuyPCB
A30: Submission & Validation
A31: IN16 | B31: Mandatory field validation | C31: 1. Leave any required field empty (e.g., "Tên nguyên liệu"). 2. Tap "Gửi yêu cầu nguyên liệu" | D31: System shows Alert "Thiếu thông tin": "Vui lòng điền đầy đủ tất cả các trường." | E31: One or more required fields are empty | F31: Passed | G31: 26/11/2025 | H31: PhuocTM | I31: Passed | J31: 26/11/2025 | K31: HoangHLN | L31: Passed | M31: 26/11/2025 | N31: DuyPCB
A32: IN17 | B32: Budget matching validation | C32: 1. Enter a total cost that does not match the phase budget. 2. Tap "Gửi yêu cầu nguyên liệu" | D32: System shows Alert "Sai số tiền" stating total cost must match the phase budget exactly | E32: Phase budget is greater than 0 | F32: Passed | G32: 26/11/2025 | H32: PhuocTM | I32: Passed | J32: 26/11/2025 | K32: HoangHLN | L32: Passed | M32: 26/11/2025 | N32: DuyPCB
A33: IN18 | B33: Successful request submission | C33: 1. Fill all valid data. 2. Ensure total cost matches budget. 3. Tap "Gửi yêu cầu nguyên liệu" | D33: Button shows "Đang gửi...", then Alert "Thành công" appears and user is navigated to the list page | E33: All input data is valid and budget is matched | F33: Passed | G33: 26/11/2025 | H33: PhuocTM | I33: Passed | J33: 26/11/2025 | K33: HoangHLN | L33: Passed | M33: 26/11/2025 | N33: DuyPCB
A34: IN19 | B34: Kiểm tra khớp ngân sách giai đoạn | C34: 1. Nhập tổng chi phí khác với ngân sách phase. 2. Nhấn Gửi | D34: Hiển thị Alert "Sai số tiền" thông báo tổng chi phí phải bằng đúng ngân sách | E34: Ngân sách giai đoạn > 0 | F34: Passed | G34: 26/11/2025 | H34: PhuocTM | I34: Passed | J34: 26/11/2025 | K34: HoangHLN | L34: Passed | M34: 26/11/2025 | N34: DuyPCB
A35: IN20 | B35: Gửi yêu cầu thành công | C35: 1. Điền đủ thông tin hợp lệ. 2. Tổng tiền khớp ngân sách. 3. Nhấn Gửi | D35: Nút chuyển sang "Đang gửi...", hiện Alert thành công và quay về trang danh sách | E35: Dữ liệu đầu vào hợp lệ | F35: Passed | G35: 26/11/2025 | H35: PhuocTM | I35: Passed | J35: 26/11/2025 | K35: HoangHLN | L35: Passed | M35: 26/11/2025 | N35: DuyPCB

Sheet OperationRequest
A2: Feature | B2: Operation Request | R2: Passed
A3: Test requirement | B3: Test Operation Request | R3: Failed
A4: Number of TCs | B4: =COUNTIF(A11:A311, "OP*") -> 22 | R4: Pending
A5: Testing Round | B5: Passed | C5: Failed | D5: Pending | E5: N/A | R5: N/A
A6: Round 1 | B6: =COUNTIF($F10:$F987,B5) -> 22 | C6: =COUNTIF($F10:$F987,C5) -> 0 | D6: =COUNTIF($F10:$F987,D5) -> 0 | E6: =COUNTIF($F10:$F987,E5) -> 0
A7: Round 2 | B7: =COUNTIF($F10:$F987,B5) -> 22 | C7: =COUNTIF($F10:$F987,C5) -> 0 | D7: =COUNTIF($F10:$F987,D5) -> 0 | E7: =COUNTIF($F10:$F987,E5) -> 0
A8: Round 3 | B8: =COUNTIF($F10:$F987,B5) -> 22 | C8: =COUNTIF($F10:$F987,C5) -> 0 | D8: =COUNTIF($F10:$F987,D5) -> 0 | E8: =COUNTIF($F10:$F987,E5) -> 0
A10: Test Case ID | B10: Test Case Description | C10: Test Case Procedure | D10: Expected Results | E10: Pre-conditions | F10: Round 1 | G10: Test date | H10: Tester | I10: Round 2 | J10: Test date | K10: Tester | L10: Round 3 | M10: Test date | N10: Tester | O10: Note
A11: Create Operation Request
A12: OP1 | B12: Verify phase selection changes selected state | C12: 1. Open operation request form 2. Tap on a different phase chip | D12: Selected phase chip shows active styling (orange background, white text), previously selected chip returns to normal styling | E12: Multiple phases available | F12: Passed | G12: 26/11/2025 | H12: PhuocTM | I12: Passed | J12: 26/11/2025 | K12: HoangHLN | L12: Passed | M12: 26/11/2025 | N12: DuyPCB
A13: OP2 | B13: Verify expense type selection between COOKING and DELIVERY | C13: 1. Open operation request form 2. Select "Nấu ăn" expense type 3. Select "Vận chuyển" expense type | D13: Selected expense type chip shows active styling, budget info updates to match selected type | E13: Form is open with phases | F13: Passed | G13: 26/11/2025 | H13: PhuocTM | I13: Passed | J13: 26/11/2025 | K13: HoangHLN | L13: Passed | M13: 26/11/2025 | N13: DuyPCB
A14: OP3 | B14: Verify budget display changes when switching expense type | C14: 1. Select a phase 2. Select "Nấu ăn" expense type 3. Select "Vận chuyển" expense type | D14: Budget box displays cookingFundsAmount when "Nấu ăn" is selected, displays deliveryFundsAmount when "Vận chuyển" is selected | E14: Phase has both cooking and delivery budget | F14: Passed | G14: 26/11/2025 | H14: PhuocTM | I14: Passed | J14: 26/11/2025 | K14: HoangHLN | L14: Passed | M14: 26/11/2025 | N14: DuyPCB
A15: OP4 | B15: Verify total cost auto-fills from budget | C15: 1. Open form for phase with budget 2. Select expense type with budget > 0 | D15: Tổng chi phí field automatically fills with the budget amount | E15: Phase has budget for selected expense type | F15: Passed | G15: 26/11/2025 | H15: PhuocTM | I15: Passed | J15: 26/11/2025 | K15: HoangHLN | L15: Passed | M15: 26/11/2025 | N15: DuyPCB
A16: OP5 | B16: Verify total cost updates when switching phase | C16: 1. Select phase A with cooking budget 100,000 2. Select phase B with cooking budget 200,000 | D16: Tổng chi phí field updates from 100,000 to 200,000 | E16: Multiple phases with different budgets | F16: Passed | G16: 26/11/2025 | H16: PhuocTM | I16: Passed | J16: 26/11/2025 | K16: HoangHLN | L16: Passed | M16: 26/11/2025 | N16: DuyPCB
A17: OP6 | B17: Verify total cost updates when switching expense type | C17: 1. Select phase with cooking budget 100,000 and delivery budget 50,000 2. Switch from "Nấu ăn" to "Vận chuyển" | D17: Tổng chi phí field updates from 100,000 to 50,000 | E17: Phase has different budgets for cooking and delivery | F17: Passed | G17: 26/11/2025 | H17: PhuocTM | I17: Passed | J17: 26/11/2025 | K17: HoangHLN | L17: Passed | M17: 26/11/2025 | N17: DuyPCB
A18: OP7 | B18: Verify currency formatting in total cost field | C18: Enter "1000000" in total cost field | D18: Field displays "1.000.000" with thousand separators | E18: User is editing total cost | F18: Passed | G18: 26/11/2025 | H18: PhuocTM | I18: Passed | J18: 26/11/2025 | K18: HoangHLN | L18: Passed | M18: 26/11/2025 | N18: DuyPCB
A19: OP8 | B19: Verify back button navigation from form | C19: 1. Open operation request form 2. Tap back button (‹) | D19: User is navigated back to the previous screen | E19: User is on form page | F19: Passed | G19: 26/11/2025 | H19: PhuocTM | I19: Passed | J19: 26/11/2025 | K19: HoangHLN | L19: Passed | M19: 26/11/2025 | N19: DuyPCB
A20: OP9 | B20: Verify "Xem danh sách yêu cầu của tôi" button navigation | C20: 1. Open operation request form 2. Tap "Xem danh sách yêu cầu của tôi" button | D20: User is navigated to operation requests list page | E20: User is on form page | F20: Passed | G20: 26/11/2025 | H20: PhuocTM | I20: Passed | J20: 26/11/2025 | K20: HoangHLN | L20: Passed | M20: 26/11/2025 | N20: DuyPCB
A21: OP10 | B21: Verify back button navigation from list page | C21: 1. Open operation requests list page 2. Tap back button (‹) | D21: User is navigated back to the previous screen | E21: User is on list page | F21: Passed | G21: 26/11/2025 | H21: PhuocTM | I21: Passed | J21: 26/11/2025 | K21: HoangHLN | L21: Passed | M21: 26/11/2025 | N21: DuyPCB
A22: OP11 | B22: Verify loading indicator on form submission | C22: 1. Fill all required fields 2. Tap "Tạo yêu cầu" button | D22: Loading indicator displays with message "Đang gửi yêu cầu..." | E22: Form is valid | F22: Passed | G22: 26/11/2025 | H22: PhuocTM | I22: Passed | J22: 26/11/2025 | K22: HoangHLN | L22: Passed | M22: 26/11/2025 | N22: DuyPCB
A23: OP12 | B23: Verify loading indicator on list page | C23: Open operation requests list page | D23: Loading indicator displays with message "Đang tải danh sách..." while data is loading | E23: User navigates to list page | F23: Passed | G23: 26/11/2025 | H23: PhuocTM | I23: Passed | J23: 26/11/2025 | K23: HoangHLN | L23: Passed | M23: 26/11/2025 | N23: DuyPCB
A24: Validate Operation Data
A25: OP13 | B25: Verify validation - no phase selected | C25: 1. Do not select any phase (no phases available) 2. Fill other required fields3. Tap "Tạo yêu cầu" button | D25: Tạo yêu cầu button is disabled when no phases available | E25: No phases are passed to form | F25: Passed | G25: 26/11/2025 | H25: PhuocTM | I25: Passed | J25: 26/11/2025 | K25: HoangHLN | L25: Passed | M25: 26/11/2025 | N25: DuyPCB
A26: OP14 | B26: Verify validation - empty title | C26: 1. Clear "Tiêu đề" field (leave empty or whitespace only) 2. Fill other required fields 3. Tap "Tạo yêu cầu" button | D26: Alert displays with title "Lỗi" and message "Vui lòng nhập tiêu đề." | E26: Phase is selected, total cost is valid | F26: Passed | G26: 26/11/2025 | H26: PhuocTM | I26: Passed | J26: 26/11/2025 | K26: HoangHLN | L26: Passed | M26: 26/11/2025 | N26: DuyPCB
A27: OP15 | B27: Verify validation - empty total cost | C27: 1. Clear "Tổng chi phí" field completely 2. Fill other required fields 3. Tap "Tạo yêu cầu" button | D27: Alert displays with title "Lỗi" and message "Tổng chi phí phải là số lớn hơn 0." | E27: Phase is selected, title is filled | F27: Passed | G27: 26/11/2025 | H27: PhuocTM | I27: Passed | J27: 26/11/2025 | K27: HoangHLN | L27: Passed | M27: 26/11/2025 | N27: DuyPCB
A28: OP16 | B28: Verify validation - total cost is zero | C28: 1. Enter "0" in "Tổng chi phí" field 2. Fill other required fields 3. Tap "Tạo yêu cầu" button | D28: Alert displays with title "Lỗi" and message "Tổng chi phí phải là số lớn hơn 0." | E28: Phase is selected, title is filled | F28: Passed | G28: 26/11/2025 | H28: PhuocTM | I28: Passed | J28: 26/11/2025 | K28: HoangHLN | L28: Passed | M28: 26/11/2025 | N28: DuyPCB
A29: OP17 | B29: Verify validation - total cost only accepts numbers | C29: 1. Try to enter letters "abc" in "Tổng chi phí" field | D29: Field only accepts numeric digits, non-numeric characters are ignored | E29: User is editing total cost | F29: Passed | G29: 26/11/2025 | H29: PhuocTM | I29: Passed | J29: 26/11/2025 | K29: HoangHLN | L29: Passed | M29: 26/11/2025 | N29: DuyPCB
A30: OP18 | B30: Verify validation - title with only whitespace | C30: 1. Enter " " (only spaces) in "Tiêu đề" field 2. Fill other required fields 3. Tap "Tạo yêu cầu" button | D30: Alert displays with title "Lỗi" and message "Vui lòng nhập tiêu đề." | E30: Phase is selected, total cost is valid | F30: Passed | G30: 26/11/2025 | H30: PhuocTM | I30: Passed | J30: 26/11/2025 | K30: HoangHLN | L30: Passed | M30: 26/11/2025 | N30: DuyPCB
A31: OP19 | B31: Verify successful form submission | C31: 1. Select a phase 2. Select expense type 3. Enter title "Chi phí nấu ăn" 4. Enter valid total cost 5. Tap "Tạo yêu cầu" button | D31: Alert displays with title "Thành công" and message "Đã tạo yêu cầu giải ngân.", after tapping "OK" user is navigated to operation requests list page | E31: All fields are valid | F31: Passed | G31: 26/11/2025 | H31: PhuocTM | I31: Passed | J31: 26/11/2025 | K31: HoangHLN | L31: Passed | M31: 26/11/2025 | N31: DuyPCB
A32: OP20 | B32: Verify error handling on submission failure | C32: 1. Fill all required fields correctly 2. Simulate network error 3. Tap "Tạo yêu cầu" button | D32: Alert displays with title "Lỗi" and error message from server or "Không thể tạo yêu cầu giải ngân." | E32: Network error occurs | F32: Passed | G32: 26/11/2025 | H32: PhuocTM | I32: Passed | J32: 26/11/2025 | K32: HoangHLN | L32: Passed | M32: 26/11/2025 | N32: DuyPCB
A33: OP21 | B33: Verify button disabled while submitting | C33: 1. Fill all required fields 2. Tap "Tạo yêu cầu" button | D33: Tạo yêu cầu button becomes disabled (opacity reduced) while request is being processed to prevent double submission | E33: Form is valid | F33: Passed | G33: 26/11/2025 | H33: PhuocTM | I33: Passed | J33: 26/11/2025 | K33: HoangHLN | L33: Passed | M33: 26/11/2025 | N33: DuyPCB
A34: OP22 | B34: Verify no phases available message | C34: Open form without passing phases parameter | D34: Giai đoạn chiến dịch section shows text "Không có giai đoạn nào được truyền vào.", "Tạo yêu cầu" button is disabled | E34: No phases passed to form | F34: Passed | G34: 26/11/2025 | H34: PhuocTM | I34: Passed | J34: 26/11/2025 | K34: HoangHLN | L34: Passed | M34: 26/11/2025 | N34: DuyPCB

Sheet MealBatchRequest
A2: Feature | B2: Meal Batch Request | R2: Passed
A3: Test requirement | B3: Test Meal Batch Request | R3: Failed
A4: Number of TCs | B4: =COUNTIF(A11:A313, "MB*") -> 20 | R4: Pending
A5: Testing Round | B5: Passed | C5: Failed | D5: Pending | E5: N/A | R5: N/A
A6: Round 1 | B6: =COUNTIF($F10:$F989,B5) -> 20 | C6: =COUNTIF($F10:$F989,C5) -> 0 | D6: =COUNTIF($F10:$F989,D5) -> 0 | E6: =COUNTIF($F10:$F989,E5) -> 0
A7: Round 2 | B7: =COUNTIF($F10:$F989,B5) -> 20 | C7: =COUNTIF($F10:$F989,C5) -> 0 | D7: =COUNTIF($F10:$F989,D5) -> 0 | E7: =COUNTIF($F10:$F989,E5) -> 0
A8: Round 3 | B8: =COUNTIF($F10:$F989,B5) -> 20 | C8: =COUNTIF($F10:$F989,C5) -> 0 | D8: =COUNTIF($F10:$F989,D5) -> 0 | E8: =COUNTIF($F10:$F989,E5) -> 0
A10: Test Case ID | B10: Test Case Description | C10: Test Case Procedure | D10: Expected Results | E10: Pre-conditions | F10: Round 1 | G10: Test date | H10: Tester | I10: Round 2 | J10: Test date | K10: Tester | L10: Round 3 | M10: Test date | N10: Tester | O10: Note
A11: Create Meal Batch
A12: MB1 | B12: Verify phase selection | C12: 1. Open meal batch form 2. Tap on a different phase chip | D12: Selected phase shows "Đang chọn" tag, phase dot changes to orange color, plannedIngredients list updates to match selected phase | E12: Multiple phases available | F12: Passed | G12: 26/11/2025 | H12: PhuocTM | I12: Passed | J12: 26/11/2025 | K12: HoangHLN | L12: Passed | M12: 26/11/2025 | N12: DuyPCB
A13: MB2 | B13: Verify ingredient selection toggle | C13: 1. Tap on an ingredient row in list | D13: Row shows "Đã chọn" badge when selected, badge count updates to show number of selected ingredients (e.g., "1 đã chọn"), tapping again deselects the ingredient | E13: PlannedIngredients exist for phase | F13: Passed | G13: 26/11/2025 | H13: PhuocTM | I13: Passed | J13: 26/11/2025 | K13: HoangHLN | L13: Passed | M13: 26/11/2025 | N13: DuyPCB
A14: MB3 | B14: Verify media picker dialog opens | C14: 1. Tap "Chụp ảnh / Chọn ảnh, video" button | D14: Alert dialog opens with three options: "Chụp từ camera", "Chọn từ thư viện", and "Hủy" | E14: User is on form page | F14: Passed | G14: 26/11/2025 | H14: PhuocTM | I14: Passed | J14: 26/11/2025 | K14: HoangHLN | L14: Passed | M14: 26/11/2025 | N14: DuyPCB
A15: MB4 | B15: Verify camera capture | C15: 1. Tap "Chụp ảnh / Chọn ảnh, video" 2. Select "Chụp từ camera" 3. Capture an image | D15: Image is added to selected files list, file chip shows file name and type (JPG/PNG) | E15: Camera permission granted | F15: Passed | G15: 26/11/2025 | H15: PhuocTM | I15: Passed | J15: 26/11/2025 | K15: HoangHLN | L15: Passed | M15: 26/11/2025 | N15: DuyPCB
A16: MB5 | B16: Verify gallery selection | C16: 1. Tap "Chụp ảnh / Chọn ảnh, video" 2. Select "Chọn từ thư viện" 3. Select up to 5 files | D16: Selected files appear as chips showing file name and type, list is limited to maximum 5 files | E16: Media library permission granted | F16: Passed | G16: 26/11/2025 | H16: PhuocTM | I16: Passed | J16: 26/11/2025 | K16: HoangHLN | L16: Passed | M16: 26/11/2025 | N16: DuyPCB
A17: MB6 | B17: Verify search functionality in list | C17: 1. Open meal batch list with multiple batches 2. Enter search text in "Tìm theo tên suất ăn..." field | D17: List filters to show only meal batches whose food name contains the search text (case-insensitive) | E17: Multiple meal batches exist | F17: Passed | G17: 26/11/2025 | H17: PhuocTM | I17: Passed | J17: 26/11/2025 | K17: HoangHLN | L17: Passed | M17: 26/11/2025 | N17: DuyPCB
A18: MB7 | B18: Verify meal batch card tap navigation | C18: 1. Tap on a meal batch card | D18: User is navigated to meal batch detail page with correct mealBatchId and campaignId parameters | E18: At least one meal batch exists | F18: Passed | G18: 26/11/2025 | H18: PhuocTM | I18: Passed | J18: 26/11/2025 | K18: HoangHLN | L18: Passed | M18: 26/11/2025 | N18: DuyPCB
A19: Update Meal Batch Status
A20: MB8 | B20: Verify update status to READY | C20: 1. Tap "Cập nhật trạng thái" button on a meal batch card 2. Confirm by tapping "OK" in the dialog | D20: Alert confirms with message 'Đánh dấu mẻ "..." đã sẵn sàng (READY)?', after OK, meal batch status updates to READY in the list, loading indicator shows during update | E20: Meal batch is not yet READY | F20: Passed | G20: 26/11/2025 | H20: PhuocTM | I20: Passed | J20: 26/11/2025 | K20: HoangHLN | L20: Passed | M20: 26/11/2025 | N20: DuyPCB
A21: MB9 | B21: Verify status label translation in detail page | C21: 1. View detail page with different statuses | D21: READY displays as "Đã sẵn sàng", "PREPARING" displays as "Đang chuẩn bị", "DELIVERED" displays as "Đã giao" | E21: Meal batch exists | F21: Passed | G21: 26/11/2025 | H21: PhuocTM | I21: Passed | J21: 26/11/2025 | K21: HoangHLN | L21: Passed | M21: 26/11/2025 | N21: DuyPCB
A22: MB10 | B22: Verify image zoom in detail page | C22: 1. Open meal batch detail with images 2. Tap on any image thumbnail | D22: Full-screen image viewer opens with dark background, zoomed image is displayed, "Đóng" button appears below image | E22: Meal batch has media images | F22: Passed | G22: 26/11/2025 | H22: PhuocTM | I22: Passed | J22: 26/11/2025 | K22: HoangHLN | L22: Passed | M22: 26/11/2025 | N22: DuyPCB
A23: MB11 | B23: Verify close image zoom | C23: 1. Open zoomed image view 2. Tap "Đóng" button or tap outside the image | D23: Image zoom overlay closes, returns to detail page view | E23: Image zoom is open | F23: Passed | G23: 26/11/2025 | H23: PhuocTM | I23: Passed | J23: 26/11/2025 | K23: HoangHLN | L23: Passed | M23: 26/11/2025 | N23: DuyPCB
A24: MB12 | B24: Verify "Xem danh sách suất ăn" button navigation | C24: 1. Open meal batch form 2. Tap "Xem danh sách suất ăn" button | D24: User is navigated to meal batch list page with correct campaignId and campaignPhaseId parameters | E24: User is on form page | F24: Passed | G24: 26/11/2025 | H24: PhuocTM | I24: Passed | J24: 26/11/2025 | K24: HoangHLN | L24: Passed | M24: 26/11/2025 | N24: DuyPCB
