Workbook
Name Z_6F1DCD5D_5DAC_4817_BF40_2B66F6F593E6_.wvu.Cols: SignIn!$E:$E
Name Z_BE54E0AD_3725_4423_92D7_4F1C045BE1BC_.wvu.Cols: RequestCreateOrganization!$E:$E
Name Z_6F1DCD5D_5DAC_4817_BF40_2B66F6F593E6_.wvu.Cols: CreateDonation!$E:$E
Name Z_BE54E0AD_3725_4423_92D7_4F1C045BE1BC_.wvu.Cols: CreateCampaign!$E:$E
Name Z_2C0D9096_8D85_462A_A9B5_0B488ADB4269_.wvu.PrintArea: Statistics!$A:$I
Name Z_BE54E0AD_3725_4423_92D7_4F1C045BE1BC_.wvu.Cols: SignUp!$E:$E
Name Z_BE54E0AD_3725_4423_92D7_4F1C045BE1BC_.wvu.Cols: CreateOperationRequest!$E:$E
Name Z_6F1DCD5D_5DAC_4817_BF40_2B66F6F593E6_.wvu.Cols: CreateMealBatch!$E:$E
Name Z_BE54E0AD_3725_4423_92D7_4F1C045BE1BC_.wvu.PrintArea: Statistics!$A:$I
Name Z_BE54E0AD_3725_4423_92D7_4F1C045BE1BC_.wvu.Cols: ConfirmSignUp!$E:$E
Name Z_6F1DCD5D_5DAC_4817_BF40_2B66F6F593E6_.wvu.Cols: CreateOperationRequest!$E:$E
Name Z_2C0D9096_8D85_462A_A9B5_0B488ADB4269_.wvu.Cols: CreateOperationRequest!$E:$E
Name Z_2C0D9096_8D85_462A_A9B5_0B488ADB4269_.wvu.Cols: ConfirmSignUp!$E:$E
Name Z_BE54E0AD_3725_4423_92D7_4F1C045BE1BC_.wvu.Cols: SignIn!$E:$E
Name Z_BE54E0AD_3725_4423_92D7_4F1C045BE1BC_.wvu.Cols: CreateMealBatch!$E:$E
Name Z_6F1DCD5D_5DAC_4817_BF40_2B66F6F593E6_.wvu.Cols: ConfirmSignUp!$E:$E
Name Z_6F1DCD5D_5DAC_4817_BF40_2B66F6F593E6_.wvu.Cols: SignUp!$E:$E
Name Z_6F1DCD5D_5DAC_4817_BF40_2B66F6F593E6_.wvu.PrintArea: Statistics!$A:$I
Name Z_2C0D9096_8D85_462A_A9B5_0B488ADB4269_.wvu.Cols: CreateCampaign!$E:$E
Name Z_2C0D9096_8D85_462A_A9B5_0B488ADB4269_.wvu.Cols: CreateDonation!$E:$E
Name Z_BE54E0AD_3725_4423_92D7_4F1C045BE1BC_.wvu.Cols: CreateIngredientRequest!$E:$E
Name Z_6F1DCD5D_5DAC_4817_BF40_2B66F6F593E6_.wvu.Cols: CreateCampaign!$E:$E
Name ACTION: #REF!
Name Z_6F1DCD5D_5DAC_4817_BF40_2B66F6F593E6_.wvu.Cols: CreateIngredientRequest!$E:$E
Name Z_2C0D9096_8D85_462A_A9B5_0B488ADB4269_.wvu.Cols: SignUp!$E:$E
Name Z_2C0D9096_8D85_462A_A9B5_0B488ADB4269_.wvu.Cols: SignIn!$E:$E
Name Z_6F1DCD5D_5DAC_4817_BF40_2B66F6F593E6_.wvu.Cols: CreateCampaignCategory!$E:$E
Name Z_2C0D9096_8D85_462A_A9B5_0B488ADB4269_.wvu.Cols: CreateIngredientRequest!$E:$E
Name Z_BE54E0AD_3725_4423_92D7_4F1C045BE1BC_.wvu.Cols: CreateDonation!$E:$E
Name Z_2C0D9096_8D85_462A_A9B5_0B488ADB4269_.wvu.Cols: CreateMealBatch!$E:$E
Name Z_6F1DCD5D_5DAC_4817_BF40_2B66F6F593E6_.wvu.Cols: RequestCreateOrganization!$E:$E
Name Z_BE54E0AD_3725_4423_92D7_4F1C045BE1BC_.wvu.Cols: CreateCampaignCategory!$E:$E
Name Z_2C0D9096_8D85_462A_A9B5_0B488ADB4269_.wvu.Cols: CreateCampaignCategory!$E:$E
Name Z_2C0D9096_8D85_462A_A9B5_0B488ADB4269_.wvu.Cols: RequestCreateOrganization!$E:$E

Sheet Guideline
A1: Guideline to make and understand Unit Test Case
A3: 1. Overview
A4: - In the template, Unit test cases are based on functions. Each sheet presents test cases for one function.
A5: - Cover: General information of the project and Unit Test cases
A6: - FunctionList: The list of Classes and Functions in the document. + To control that the number of Unit TC meets customer's requirement or the norm, user should fill value for 'Normal number of Test cases/KLOC'.
A7: + Click on Function link to open the related Test cases of the function. Note: You should create new Function sheet before creating the link
A8: - Test Report: provive the overview results of Functions Unit test: Test coverage, Test successful coverage (Summary, for normal/abnormal/boundary cases)
A9: Note: Should check the formula of "Sub Total" if you add more functions
A11: 2. Content in Test function sheet
A12: 2.1 Combination of test cases.
A13: - To verify that number of Unit TC meets customer's requirement or not. User has to fill number LOC of tested function and fill value of 'Normal number test cases/KLOC' item in FunctionList sheet, which is required by customer or normal value. The number of lacked TC is shown in 'Lack of test cases' item.
A14: - If the number of Unit TC does not meet the requirement, creator should explain the reasons.
... A47: - Test requirement: Brief description about requirements which are tested in this function, it is not mandatory.

Sheet Cover
B2: UNIT TEST DOCUMENT
A4: Project Name | B4: FoodFund - A crowdfunding system for food preparation and distribution to support communities in need | E4: Creator | F4: PhuocTM
A5: Project Code | B5: FA25SE52 | E5: Issue Date | F5: 30/11/2025
A6: Document Code | B6: =B5&"_"&"Test Report"&"_"&"v1.1" -> FA25SE52_Test Report_v1.1 | E6: Version | F6: 1.1
A9: Record of change
A10: Effective Date | B10: Version | C10: Change Item | D10: *A,D,M | E10: Change description | F10: Reference
A11: 30/10/2025 | B11: 1.0 | C11: All | D11: A | E11: Add new unit test document
A12: 30/11/2025 | B12: 1.1 | C12: Statistics, Functions | D12: A | E12: Add more unit tests
A13: 14/12/2025 | B13: 1.2 | C13: Statistics, Functions | D13: A | E13: Add unit tests for create Campaign Category | F13: CreateCampaignCategory

Sheet Statistics
A2: UNIT TEST REPORT
A4: Project Name | B4: =Cover!B4 -> FoodFund - A crowdfunding system for food preparation and distribution to support communities in need | D4: Creator | F4: PhuocTM
A5: Project Code | B5: =Cover!B5 -> FA25SE52 | D5: Reviewer/Approver | F5: Nguyễn Minh Sang
A6: Document Code | B6: =B5&"_"&"Test Report"&"_"&"v1.1" -> FA25SE52_Test Report_v1.1 | D6: Issue Date | F6: 30/11/2025
A7: Notes
A11: No | B11: Function code | C11: Passed | D11: Failed | E11: Untested | F11: N | G11: A | H11: B | I11: Total Test Cases
A12: 1 | B12: SignUp | C12: =SignUp!A7 -> 7 | D12: =SignUp!C7 -> 0 | E12: =SignUp!F7 -> 0 | F12: =SignUp!L7 -> 1 | G12: =SignUp!M7 -> 3 | H12: =SignUp!N7 -> 3 | I12: =SignUp!O7 -> 7
A13: 2 | B13: SignIn | C13: =SignIn!A7 -> 8 | D13: =SignIn!C7 -> 0 | E13: =SignIn!F7 -> 0 | F13: =SignIn!L7 -> 1 | G13: =SignIn!M7 -> 5 | H13: =SignIn!N7 -> 2 | I13: =SignIn!O7 -> 8
A14: 3 | B14: ConfirmSignUp | C14: =ConfirmSignUp!A7 -> 8 | D14: =ConfirmSignUp!C7 -> 0 | E14: =ConfirmSignUp!F7 -> 0 | F14: =ConfirmSignUp!L7 -> 1 | G14: =ConfirmSignUp!M7 -> 4 | H14: =ConfirmSignUp!N7 -> 3 | I14: =ConfirmSignUp!O7 -> 8
A15: 4 | B15: RequestCreateOrganization | C15: =RequestCreateOrganization!A7 -> 13 | D15: =RequestCreateOrganization!C7 -> 0 | E15: =RequestCreateOrganization!F7 -> 0 | F15: =RequestCreateOrganization!L7 -> 2 | G15: =RequestCreateOrganization!M7 -> 4 | H15: =RequestCreateOrganization!N7 -> 7 | I15: =RequestCreateOrganization!O7 -> 13
A16: 5 | B16: CreateCampaign | C16: =CreateCampaign!A7 -> 19 | D16: =CreateCampaign!C7 -> 0 | E16: =CreateCampaign!F7 -> 0 | F16: =CreateCampaign!L7 -> 1 | G16: =CreateCampaign!M7 -> 7 | H16: =CreateCampaign!N7 -> 11 | I16: =CreateCampaign!O7 -> 19
A17: 6 | B17: CreateDonation | C17: =CreateDonation!A7 -> 16 | D17: =CreateDonation!C7 -> 0 | E17: =CreateDonation!F7 -> 0 | F17: =CreateDonation!L7 -> 4 | G17: =CreateDonation!M7 -> 4 | H17: =CreateDonation!N7 -> 8 | I17: =CreateDonation!O7 -> 16
A18: 7 | B18: CreateOperationRequest | C18: =CreateOperationRequest!A7 -> 13 | D18: =CreateOperationRequest!C7 -> 0 | E18: =CreateOperationRequest!F7 -> 0 | F18: =CreateOperationRequest!K7 -> 2 | G18: =CreateOperationRequest!L7 -> 5 | H18: =CreateOperationRequest!M7 -> 6 | I18: =CreateOperationRequest!N7 -> 13
A19: 8 | B19: CreateIngredientRequest | C19: =CreateIngredientRequest!A7 -> 10 | D19: =CreateIngredientRequest!C7 -> 0 | E19: =CreateIngredientRequest!F7 -> 0 | F19: =CreateIngredientRequest!L7 -> 1 | G19: =CreateIngredientRequest!M7 -> 3 | H19: =CreateIngredientRequest!N7 -> 6 | I19: =CreateIngredientRequest!O7 -> 10
A20: 9 | B20: CreateMealBatch | C20: =CreateMealBatch!A7 -> 17 | D20: =CreateMealBatch!C7 -> 0 | E20: =CreateMealBatch!F7 -> 0 | F20: =CreateMealBatch!L7 -> 2 | G20: =CreateMealBatch!M7 -> 6 | H20: =CreateMealBatch!N7 -> 9 | I20: =CreateMealBatch!O7 -> 17
A21: 10 | B21: CreateCampaignCategory | C21: =CreateCampaignCategory!A7 -> 9 | D21: =CreateCampaignCategory!C7 -> 0 | E21: =CreateCampaignCategory!F7 -> 0 | F21: =CreateCampaignCategory!L7 -> 1 | G21: =CreateCampaignCategory!M7 -> 5 | H21: =CreateCampaignCategory!N7 -> 3 | I21: =CreateCampaignCategory!O7 -> 9
B22: Sub total | C22: =SUM(C12:C21) -> 120 | D22: =SUM(D10:D21) -> 0 | E22: =SUM(E10:E21) -> 0 | F22: =SUM(F12:F21) -> 16 | G22: =SUM(G12:G21) -> 46 | H22: =SUM(H12:H21) -> 58 | I22: =SUM(I12:I21) -> 120
B24: Test coverage | D24: =(C22+D22)*100/(I22) -> 100 | E24: %
B25: Test successful coverage | D25: =C22*100/(I22) -> 100 | E25: %
B26: Normal case | D26: =F22*100/I22 -> 13.333333 | E26: %
B27: Abnormal case | D27: =G22*100/I22 -> 38.333333 | E27: %
B28: Boundary case | D28: =H22*100/I22 -> 48.333333 | E28: %

Sheet Functions
E2: Function List
A4: Project Name | E4: FoodFund - A crowdfunding system for food preparation and distribution to support communities in need
A5: Project Code | E5: =Cover!B5 -> FA25SE52
A6: Normal number of Test cases/KLOC | E6: 100
A7: Test Environment Setup Description
A10: No | B10: Requirement Name | C10: Class Name | D10: Function Name | E10: Function Code(Optional) | F10: Sheet Name | G10: Description | H10: Pre-Condition
A11: 1 | C11: RegistrationResolver | D11: signUp | E11: SU | F11: SignUp
A12: 2 | C12: AuthenticationResolver | D12: signIn | E12: SI | F12: SignIn
A13: 3 | C13: RegistrationResolver | D13: confirmSignUp | E13: CSU | F13: ConfirmSignUp
A14: 4 | C14: DonorProfileResolver | D14: requestCreateOrganization | E14: RCO | F14: RequestCreateOrganization
A15: 5 | C15: CampaignMutationResolver | D15: createCampaign | E15: CC | F15: CreateCampaign
A16: 6 | C16: DonorMutationResolver | D16: createDonation | E16: CD | F16: CreateDonation
A17: 7 | C17: OperationRequestMutationResolver | D17: createOperationRequest | E17: COR | F17: CreateOperationRequest
A18: 8 | C18: IngredientRequestMutationResolver | D18: createIngredientRequest | E18: CIR | F18: CreateIngredientRequest
A19: 9 | C19: MealBatchMutationResolver | D19: createMealBatch | E19: CMB | F19: CreateMealBatch
A20: 10 | C20: CampaignCategoryMutationResolver | D20: createCampaignCategory | E20: CCC | F20: CreateCampaignCategory

Sheet SignUp
A2: Function Code | C2: =Functions!E11 -> SU | F2: Function Name | L2: =Functions!D11 -> signUp
A3: Created By | C3: PhuocTM | F3: Executed By | L3: PhuocTM
A4: Lines of code | C4: 100 | F4: Lack of test cases | L4: =IF(Functions!E6<>"N/A",SUM(C4*Functions!E6/1000,-O7),"N/A") -> 3
A5: Test requirement | C5: Verify sign up function work properly
A6: Passed | C6: Failed | F6: Untested | L6: N/A/B | O6: Total Test Cases
A7: =COUNTIF(F41:HQ41,"P") -> 7 | C7: =COUNTIF(F41:HQ41,"F") -> 0 | F7: =SUM(O7,-A7,-C7) -> 0 | L7: =COUNTIF(E40:HQ40,"N") -> 1 | M7: =COUNTIF(E40:HQ40,"A") -> 3 | N7: =COUNTIF(E40:HQ40,"B") -> 3 | O7: =COUNTA(E9:HT9) -> 7
F9: UTCID01 | G9: UTCID02 | H9: UTCID03 | I9: UTCID04 | J9: UTCID05 | K9: UTCID06 | L9: UTCID07
A10: Condition | B10: Precondition
D11: Can connect with server | F11: O | G11: O | H11: O | I11: O | J11: O | K11: O | L11: O
B12: email
D13: newuser@example.com | F13: O | H13: O | J13: O | K13: O
D14: existing@example.com | G14: O
D15: "" | I15: O
D16: invalidemail | L16: O
B17: name
D18: "" | K18: O
D19: Minh Phuoc | F19: O | G19: O | H19: O | I19: O | J19: O | L19: O
B20: Password
D21: "" | J21: O
D22: 123 | H22: O
D23: 123456 | F23: O | G23: O | I23: O | K23: O | L23: O
A24: Confirm | B24: Return
D25: T | F25: O
D26: F | G26: O | H26: O | I26: O | J26: O | K26: O | L26: O
B27: Exception
D28: Throw UsernameExistsException | G28: O
D29: Throw InvalidPasswordException | H29: O
D30: Throw Validation Error | I30: O | J30: O | K30: O | L30: O
B32: Log message
D33: "User registered successfully. Please check your email for verification code." | F33: O
D34: "An account with the given email already exists" | G34: O
D35: "Password not long enough" | H35: O
D36: "Email is required" | I36: O
D37: "Password is required" | J37: O
D38: "Name is required" | K38: O
D39: "Invalid email format" | L39: O
A40: Result | B40: Type(N : Normal, A : Abnormal, B : Boundary) | F40: N | G40: A | H40: A | I40: B | J40: B | K40: B | L40: A
B41: Passed/Failed | F41: P | G41: P | H41: P | I41: P | J41: P | K41: P | L41: P
B42: Executed Date | F42: 45963 | G42: 45963 | H42: 45963 | I42: 45963 | J42: 45963 | K42: 45963 | L42: 45963
B43: Defect ID

Sheet ConfirmSignUp
A2: Function Code | C2: =Functions!E13 -> CSU | F2: Function Name | L2: =Functions!D13 -> confirmSignUp
A3: Created By | C3: PhuocTM | F3: Executed By | L3: PhuocTM
A4: Lines of code | C4: 100 | F4: Lack of test cases | L4: =IF(Functions!E6<>"N/A",SUM(C4*Functions!E6/1000,-O7),"N/A") -> 2
A5: Test requirement | C5: Verify confirm sign up function work properly
A6: Passed | C6: Failed | F6: Untested | L6: N/A/B | O6: Total Test Cases
A7: =COUNTIF(F41:HQ41,"P") -> 8 | C7: =COUNTIF(F41:HQ41,"F") -> 0 | F7: =SUM(O7,-A7,-C7) -> 0 | L7: =COUNTIF(E40:HQ40,"N") -> 1 | M7: =COUNTIF(E40:HQ40,"A") -> 4 | N7: =COUNTIF(E40:HQ40,"B") -> 3 | O7: =COUNTA(E9:HT9) -> 8
F9: UTCID01 | G9: UTCID02 | H9: UTCID03 | I9: UTCID04 | J9: UTCID05 | K9: UTCID06 | L9: UTCID07 | M9: UTCID08
A10: Condition | B10: Precondition
D11: Can connect with server | F11: O | G11: O | H11: O | I11: O | J11: O | K11: O | L11: O | M11: O
B12: email
D13: test@example.com | F13: O | G13: O | H13: O | K13: O
D14: notexisting@example.com | I14: O
D15: "" | L15: O
D16: verified@example.com | J16: O
D17: notvalidemail | M17: O
B18: confirmationCode
D19: "" | K19: O
D20: 567891 | G20: O
D21: 123456 | F21: O | H21: O | I21: O | J21: O | L21: O | M21: O
A22: Confirm | B22: Return
D23: T | F23: O
D24: F | G24: O | H24: O | I24: O | J24: O | K24: O | L24: O | M24: O
B25: Exception
D26: Throw CodeMismatchException | G26: O
D27: Throw ExpiredCodeException | H27: O
D28: Throw UserNotFoundException | I28: O
D29: Throw UserVerifiedAlreadyException | J29: O
D30: Throw Validation Error | K30: O | L30: O | M30: O
B31: Log message
D32: "Email confirmed successfully. You can now sign in" | F32: O
B33: "Invalid verification code provided" | G33: O
B34: "Invalid code provided, please request a code again" | H34: O
B35: "User does not exist" | I35: O
B36: "User cannot be confirmed" | J36: O
B37: "Confirmation code is required" | K37: O
B38: "Email is required" | L38: O
B39: "Invalid email format" | M39: O
A40: Result | B40: Type(N : Normal, A : Abnormal, B : Boundary) | F40: N | G40: A | H40: A | I40: A | J40: B | K40: B | L40: B | M40: A
B41: Passed/Failed | F41: P | G41: P | H41: P | I41: P | J41: P | K41: P | L41: P | M41: P
B42: Executed Date | F42: 45963 | G42: 45963 | H42: 45963 | I42: 45963 | J42: 45963 | K42: 45963 | L42: 45963 | M42: 45963
...

Sheet SignIn
A2: Function Code | C2: =Functions!E12 -> SI | F2: Function Name | L2: =Functions!D12 -> signIn
A3: Created By | C3: PhuocTM | F3: Executed By | L3: PhuocTM
A4: Lines of code | C4: 100 | F4: Lack of test cases | L4: =IF(Functions!E6<>"N/A",SUM(C4*Functions!E6/1000,-O7),"N/A") -> 2
A5: Test requirement | C5: Verify sign in function work properly
A6: Passed | C6: Failed | F6: Untested | L6: N/A/B | O6: Total Test Cases
A7: =COUNTIF(F43:HQ43,"P") -> 8 | C7: =COUNTIF(F43:HQ43,"F") -> 0 | F7: =SUM(O7,-A7,-C7) -> 0 | L7: =COUNTIF(E42:HQ42,"N") -> 1 | M7: =COUNTIF(E42:HQ42,"A") -> 5 | N7: =COUNTIF(E42:HQ42,"B") -> 2 | O7: =COUNTA(E9:HT9) -> 8
F9: UTCID01 | G9: UTCID02 | H9: UTCID03 | I9: UTCID04 | J9: UTCID05 | K9: UTCID06 | L9: UTCID07 | M9: UTCID08
A10: Condition | B10: Precondition
D11: Can connect with server | F11: O | G11: O | H11: O | I11: O | J11: O | K11: O | L11: O | M11: O
B12: email
D13: test@example.com | F13: O | H13: O | J13: O
D14: notexisting@example.com | G14: O
D15: "" | I15: O
D16: invalidemail | K16: O
D17: unverified@example.com | M17: O
D18: inactive@example.com | L18: O
B19: Password
D20: "" | J20: O
D21: 123 | H21: O
D22: 123456 | F22: O | G22: O | I22: O | K22: O | L22: O | M22: O
A23: Confirm | B23: Return
D24: T | F24: O
D25: F | G25: O | H25: O | I25: O | J25: O | K25: O | L25: O | M25: O
B26: Exception
D27: Throw UserNotFoundException | G27: O
D28: Throw NotAuthorizedException | H28: O
D29: Throw Validation Error | I29: O | J29: O | K29: O
D30: Throw UserNotConfirmedException | M30: O
D31: Throw UnauthorizedException | L31: O
B33: Log message
D34: "Sign in successful" | F34: O
D35: "User does not exist" | G35: O
D36: "Incorrect username or password" | H36: O
D37: "Email is required" | I37: O
D38: "Password is required" | J38: O
D39: "Invalid email format" | K39: O
D40: "User is not confirmed" | M40: O
D41: "User is not active" | L41: O
A42: Result | B42: Type(N : Normal, A : Abnormal, B : Boundary) | F42: N | G42: A | H42: A | I42: B | J42: B | K42: A | L42: A | M42: A
B43: Passed/Failed | F43: P | G43: P | H43: P | I43: P | J43: P | K43: P | L43: P | M43: P
...

Sheet RequestCreateOrganization
A2: Function Code | C2: =Functions!E14 -> RCO | F2: Function Name | L2: =Functions!D14 -> requestCreateOrganization
A3: Created By | C3: PhuocTM | F3: Executed By | L3: PhuocTM
A4: Lines of code | C4: 100 | F4: Lack of test cases | L4: =IF(Functions!E6<>"N/A",SUM(C4*Functions!E6/1000,-O7),"N/A") -> -3
A5: Test requirement
A6: Passed | C6: Failed | F6: Untested | L6: N/A/B | O6: Total Test Cases
A7: =COUNTIF(F70:HR70,"P") -> 13 | C7: =COUNTIF(F70:HR70,"F") -> 0 | F7: =SUM(O7,-A7,-C7) -> 0 | L7: =COUNTIF(E69:HR69,"N") -> 2 | M7: =COUNTIF(E69:HR69,"A") -> 4 | N7: =COUNTIF(E69:HR69,"B") -> 7 | O7: =COUNTA(E9:HU9) -> 13
F9: UTCID01 | G9: UTCID02 | H9: UTCID03 | I9: UTCID04 | J9: UTCID05 | K9: UTCID06 | L9: UTCID07 | M9: UTCID08 | N9: UTCID09 | O9: UTCID10 | P9: UTCID11 | Q9: UTCID12 | R9: UTCID13
A10: Condition | B10: Precondition
D11: Can connect with server | F11: O | G11: O | H11: O | I11: O | J11: O | K11: O | L11: O | M11: O | N11: O | O11: O | P11: O | Q11: O | R11: O
B12: name
D13: Tổ chức Cứu Trợ Thực Phẩm Hồ Chí Minh | F13: O | G13: O | I13: O | J13: O | K13: O | L13: O | M13: O | N13: O | O13: O | P13: O | Q13: O | R13: O
D14: "" | H14: O
B15: activity_field
D16: Hỗ trợ lương thực cộng đồng | F16: O | G16: O | H16: O | I16: O | J16: O | K16: O | M16: O | N16: O | O16: O | P16: O | Q16: O | R16: O
D17: "" | L17: O
B18: address
D19: 123 Đường Pasteur, Quận 1, TP.HCM | F19: O | G19: O | H19: O | I19: O | J19: O | K19: O | L19: O | N19: O | O19: O | P19: O | Q19: O | R19: O
D20: "" | M20: O
B21: description
D22: Tổ chức phi lợi nhuận chuyên cung cấp suất ăn cho người nghèo | F22: O | G22: O | H22: O | I22: O | J22: O | K22: O | L22: O | M22: O | O22: O | P22: O | Q22: O | R22: O
D23: "" | N23: O
B24: representative_name
D25: Huỳnh Văn A | F25: O | H25: O | I25: O | J25: O | K25: O | L25: O | M25: O | N25: O | O25: O | P25: O | Q25: O | R25: O
D26: Trần Văn B | G26: O
B27: representative_identity_number
D28: 111222333335 | F28: O | G28: O | H28: O | I28: O | J28: O | K28: O | L28: O | M28: O | N28: O | P28: O | Q28: O | R28: O
D29: "" | O29: O
B30: bank_account_name
D31: Huỳnh Văn A | F31: O | G31: O | H31: O | I31: O | J31: O | K31: O | L31: O | M31: O | N31: O | O31: O | P31: O | Q31: O | R31: O
B32: bank_account_number
D33: 1022292912 | F33: O | G33: O | H33: O | I33: O | J33: O | K33: O | L33: O | M33: O | N33: O | O33: O | Q33: O | R33: O
D34: "" | P34: O
B35: bank_name
D36: Ngân hàng TMCP Ngoại Thương Việt Nam | F36: O | G36: O | H36: O | I36: O | J36: O | K36: O | L36: O | M36: O | N36: O | O36: O | P36: O | R36: O
D37: "" | Q37: O
B38: bank_short_name
D39: VCB | F39: O | G39: O | H39: O | I39: O | J39: O | K39: O | L39: O | M39: O | N39: O | O39: O | P39: O | Q39: O | R39: O
B40: email
D41: foodfund.last929@aleeas.com | F41: O | G41: O | H41: O | J41: O | K41: O | L41: O | M41: O | N41: O | O41: O | P41: O | Q41: O | R41: O
D42: invalid-email | I42: O
...

Sheet CreateCampaign
A2: Function Code | C2: =Functions!E15 -> CC | F2: Function Name | L2: =Functions!D15 -> createCampaign
A3: Created By | C3: LuyenHD | F3: Executed By | L3: LuyenHD
A4: Lines of code | C4: 180 | F4: Lack of test cases | L4: =IF(Functions!E6<>"N/A",SUM(C4*Functions!E6/1000,-O7),"N/A") -> -1
A5: Test requirement
A6: Passed | C6: Failed | F6: Untested | L6: N/A/B | O6: Total Test Cases
A7: =COUNTIF(F75:HU75,"P") -> 19 | C7: =COUNTIF(F75:HU75,"F") -> 0 | F7: =SUM(O7,-A7,-C7) -> 0 | L7: =COUNTIF(E74:HU74,"N") -> 1 | M7: =COUNTIF(E74:HU74,"A") -> 7 | N7: =COUNTIF(E74:HU74,"B") -> 11 | O7: =COUNTA(E9:HX9) -> 19
F9: UTCID01 | G9: UTCID02 | H9: UTCID03 | I9: UTCID04 | J9: UTCID05 | K9: UTCID06 | L9: UTCID07 | M9: UTCID08 | N9: UTCID09 | O9: UTCID10 | P9: UTCID11 | Q9: UTCID12 | R9: UTCID13 | S9: UTCID14 | T9: UTCID15 | U9: UTCID16 | V9: UTCID17 | W9: UTCID18 | X9: UTCID19
A10: Condition | B10: Precondition
D11: Logged in with the fundraiser account | F11: O | G11: O | H11: O | I11: O | J11: O | K11: O | L11: O | M11: O | N11: O | O11: O | P11: O | Q11: O | R11: O | S11: O | T11: O | U11: O | V11: O | W11: O | X11: O
B12: title
D13: Chương trình Suất ăn miễn phí | F13: O | I13: O | J13: O | K13: O | L13: O | M13: O | N13: O | O13: O | P13: O | Q13: O | R13: O | S13: O | T13: O | U13: O | V13: O | W13: O | X13: O
D14: "" | G14: O
D15: test | H15: O
B16: description
D17: Quyên góp để nấu những suất ăn đầy đủ chất dinh dưỡng | F17: O | G17: O | H17: O | K17: O | L17: O | M17: O | N17: O | O17: O | P17: O | Q17: O | R17: O | S17: O | T17: O | U17: O | V17: O | W17: O | X17: O
D18: "" | I18: O
D19: short description | J19: O
B20: coverImageFileKey
D21: campaigns/2025-12-07/baa19da8-temp-1765072886884-19eaa51c-5061-7097-52d0-fa60f6db38e1.jpg | F21: O | G21: O | H21: O | I21: O | J21: O | N21: O | O21: O | P21: O | Q21: O | R21: O | S21: O | T21: O | U21: O | V21: O | W21: O | X21: O
D22: invalid-key | K22: O
D23: wrong/path/file.jpg | L23: O
D24: "" | M24: O
B25: targetAmount
D26: 2500000 | F26: O | G26: O | H26: O | I26: O | J26: O | K26: O | L26: O | M26: O | R26: O | S26: O | T26: O | U26: O | V26: O | W26: O | X26: O
D27: 0 | N27: O
D28: -1000 | O28: O
D29: abc | P29: O
D30: "" | Q30: O
B31: fundraisingStartDate
D32: 45658 | F32: O | G32: O | H32: O | I32: O | J32: O | K32: O | L32: O | M32: O | N32: O | O32: O | P32: O | Q32: O | S32: O | U32: O | V32: O | W32: O | X32: O
D33: 45689 | R33: O
D34: null | T34: O
B35: fundraisingEndDate
D36: 45689 | F36: O | G36: O | H36: O | I36: O | J36: O | K36: O | L36: O | M36: O | N36: O | O36: O | P36: O | Q36: O | T36: O | V36: O | W36: O | X36: O
D37: 45658 | R37: O | S37: O
D38: null | U38: O
B39: categoryId
D40: 745665c5-9891-44a2-acc2-748e032214ce | F40: O | G40: O | H40: O | I40: O | J40: O | K40: O | L40: O | M40: O | N40: O | O40: O | P40: O | Q40: O | R40: O | S40: O | T40: O | U40: O | X40: O
D41: not-exist-uuid | V41: O
D42: invalid-id | W42: O
...

Sheet CreateDonation
A2: Function Code | C2: =Functions!E16 -> CD | F2: Function Name | L2: =Functions!D16 -> createDonation
A3: Created By | C3: PhuocTM | F3: Executed By | L3: PhuocTM
A4: Lines of code | C4: 100 | F4: Lack of test cases | L4: =IF(Functions!E6<>"N/A",SUM(C4*Functions!E6/1000,-O7),"N/A") -> -6
A5: Test requirement
A6: Passed | C6: Failed | F6: Untested | L6: N/A/B | O6: Total Test Cases
A7: =COUNTIF(F50:HR50,"P") -> 16 | C7: =COUNTIF(F50:HR50,"F") -> 0 | F7: =SUM(O7,-A7,-C7) -> 0 | L7: =COUNTIF(E49:HR49,"N") -> 4 | M7: =COUNTIF(E49:HR49,"A") -> 4 | N7: =COUNTIF(E49:HR49,"B") -> 8 | O7: =COUNTA(E9:HU9) -> 16
F9: UTCID01 | G9: UTCID02 | H9: UTCID03 | I9: UTCID04 | J9: UTCID05 | K9: UTCID06 | L9: UTCID07 | M9: UTCID08 | N9: UTCID09 | O9: UTCID10 | P9: UTCID11 | Q9: UTCID12 | R9: UTCID13 | S9: UTCID14 | T9: UTCID15 | U9: UTCID16
A10: Condition | B10: Precondition
D11: Can connect with server | F11: O | G11: O | H11: O | I11: O | J11: O | K11: O | L11: O | M11: O | N11: O | O11: O | P11: O | Q11: O | R11: O | S11: O | T11: O | U11: O
B12: donorId
D13: f9aa955c-4051-709c-4ffc-005fd148ef48 | F13: O | G13: O | J13: O | K13: O | L13: O | M13: O | N13: O | O13: O | P13: O | Q13: O | R13: O | S13: O | T13: O | U13: O
D14: null | H14: O | I14: O
B15: campaignId
D16: 745665c5-9891-44a2-acc2-748e032214ce | F16: O | G16: O | H16: O | I16: O | N16: O | O16: O | P16: O | Q16: O | R16: O | S16: O | T16: O | U16: O
D17: "" | J17: O
D18: null | K18: O
D19: invalid-id | L19: O
D20: not-exist-uuid | M20: O
B21: amount
D22: 100000 | F22: O | G22: O | H22: O | I22: O | J22: O | K22: O | L22: O | M22: O | U22: O
D23: 0 | N23: O
D24: -1000 | O24: O
D25: 999 | P25: O
D26: 1000 | Q26: O
D27: 500000000 | R27: O
D28: 500000001 | S28: O
D29: null | T29: O
B30: isAnonymous
D31: TRUE | G31: O | H31: O | J31: O | K31: O | L31: O | M31: O | N31: O | O31: O | P31: O | Q31: O | R31: O | S31: O | T31: O
D32: FALSE | F32: O | I32: O
D33: "yes" | U33: O
A34: Confirm | B34: Return
D35: T | F35: O | G35: O | H35: O | I35: O | Q35: O | R35: O
D36: F | J36: O | K36: O | L36: O | M36: O | N36: O | O36: O | P36: O | S36: O | T36: O | U36: O
B37: Exception
D38: Throw Validation Error | J38: O | K38: O | L38: O | N38: O | O38: O | P38: O | S38: O | T38: O | U38: O
D39: Throw NotFoundException | M39: O
B40: Log message
D41: "Create Donation Success" | F41: O | G41: O | H41: O | I41: O | Q41: O | R41: O
B42: "Campaign ID is required" | J42: O | K42: O
...

Sheet CreateOperationRequest
A2: Function Code | C2: =Functions!E17 -> COR | F2: Function Name | K2: =Functions!D17 -> createOperationRequest
A3: Created By | C3: LuyenHD | F3: Executed By | K3: LuyenHD
A4: Lines of code | C4: 110 | F4: Lack of test cases | K4: =IF(Functions!E6<>"N/A",SUM(C4*Functions!E6/1000,-N7),"N/A") -> -2
A5: Test requirement
A6: Passed | C6: Failed | F6: Untested | K6: N/A/B | N6: Total Test Cases
A7: =COUNTIF(F52:HQ52,"P") -> 13 | C7: =COUNTIF(F52:HQ52,"F") -> 0 | F7: =SUM(N7,-A7,-C7) -> 0 | K7: =COUNTIF(E51:HQ51,"N") -> 2 | L7: =COUNTIF(E51:HQ51,"A") -> 5 | M7: =COUNTIF(E51:HQ51,"B") -> 6 | N7: =COUNTA(E9:HT9) -> 13
F9: UTCID01 | G9: UTCID02 | H9: UTCID03 | I9: UTCID04 | J9: UTCID05 | K9: UTCID06 | L9: UTCID07 | M9: UTCID08 | N9: UTCID09 | O9: UTCID10 | P9: UTCID11 | Q9: UTCID12 | R9: UTCID13
A10: Condition | B10: Precondition
D11: Logged in with the kitchen staff/fundraiser account | F11: O | G11: O | H11: O | I11: O | J11: O | K11: O | L11: O | M11: O | N11: O | O11: O | P11: O | Q11: O | R11: O
B12: campaignPhaseId
D13: 745665c5-9891-44a2-acc2-748e032214ce | F13: O | G13: O | J13: O | K13: O | L13: O | M13: O | N13: O | O13: O | P13: O | Q13: O | R13: O
D14: null | H14: O
D15: not-exist-uuid | I15: O
B16: title
D17: Chi phí nấu ăn ngày 1 | F17: O | G17: O | H17: O | I17: O | L17: O | M17: O | N17: O | O17: O | P17: O | Q17: O | R17: O
D18: "" | J18: O
D19: test | K19: O
B20: totalCost
D21: 500000 | F21: O | G21: O | H21: O | I21: O | J21: O | K21: O | Q21: O | R21: O
D22: "" | L22: O
D23: 0 | M23: O
D24: -100000 | N24: O
D25: abc | O25: O
D26: 9999999999999 | P26: O
B27: expenseType
D28: COOKING | F28: O | H28: O | I28: O | J28: O | K28: O | L28: O | M28: O | N28: O | O28: O | P28: O
D29: DELIVERY | G29: O
D30: null | Q30: O
D31: INVALID | R31: O
A32: Confirm | B32: Return
D33: T | F33: O | G33: O
D34: F | H34: O | I34: O | J34: O | K34: O | L34: O | M34: O | N34: O | O34: O | P34: O | Q34: O | R34: O
B35: Exception
D36: Throw Validation Error | H36: O | J36: O | K36: O | L36: O | Q36: O | R36: O
D37: Throw NotFoundException | I37: O
D38: Throw BadRequestException | M38: O | N38: O | O38: O | P38: O
B39: Log message
D40: "Create operation request successfully" | F40: O | G40: O
B41: "Campaign phase ID is required" | H41: O
B42: "Campaign phase not found" | I42: O
...

Sheet CreateIngredientRequest
A2: Function Code | C2: =Functions!E18 -> CIR | F2: Function Name | L2: =Functions!D18 -> createIngredientRequest
A3: Created By | C3: LuyenHD | F3: Executed By | L3: LuyenHD
A4: Lines of code | C4: 100 | F4: Lack of test cases | L4: =IF(Functions!E6<>"N/A",SUM(C4*Functions!E6/1000,-O7),"N/A") -> 0
A5: Test requirement
A6: Passed | C6: Failed | F6: Untested | L6: N/A/B | O6: Total Test Cases
A7: =COUNTIF(F43:HR43,"P") -> 10 | C7: =COUNTIF(F43:HR43,"F") -> 0 | F7: =SUM(O7,-A7,-C7) -> 0 | L7: =COUNTIF(E42:HR42,"N") -> 1 | M7: =COUNTIF(E42:HR42,"A") -> 3 | N7: =COUNTIF(E42:HR42,"B") -> 6 | O7: =COUNTA(E9:HU9) -> 10
F9: UTCID01 | G9: UTCID02 | H9: UTCID03 | I9: UTCID04 | J9: UTCID05 | K9: UTCID06 | L9: UTCID07 | M9: UTCID08 | N9: UTCID09 | O9: UTCID10
A10: Condition | B10: Precondition
D11: Logged in with the kitchen staff account | F11: O | G11: O | H11: O | I11: O | J11: O | K11: O | L11: O | M11: O | N11: O | O11: O
B12: campaignPhaseId
D13: 745665c5-9891-44a2-acc2-748e032214ce | F13: O | J13: O | K13: O | L13: O | M13: O | N13: O | O13: O
D14: "" | G14: O
D15: null | H15: O
D16: not-exist-uuid | I16: O
B17: totalCost
D18: 500000 | F18: O | G18: O | H18: O | I18: O | N18: O | O18: O
D19: "" | J19: O
D20: 0 | K20: O
D21: -100000 | L21: O
D22: abc | M22: O
B23: items
D24: [valid item] | F24: O | G24: O | H24: O | I24: O | J24: O | K24: O | L24: O | M24: O
D25: [] | N25: O
D26: null | O26: O
A27: Confirm | B27: Return
D28: T | F28: O
D29: F | G29: O | H29: O | I29: O | J29: O | K29: O | L29: O | M29: O | N29: O | O29: O
B30: Exception
D31: Throw Validation Error | G31: O | H31: O | J31: O | O31: O
D32: Throw NotFoundException | I32: O
D33: Throw BadRequestException | K33: O | L33: O | M33: O | N33: O
B34: Log message
D35: "Create ingredient request successfully" | F35: O
B36: "Campaign phase ID is required" | G36: O | H36: O
B37: "Campaign phase not found" | I37: O
B38: "totalCost must be a non-empty string" | J38: O
B39: "Total cost must be greater than 0" | K39: O | L39: O
B40: "Invalid total cost" | M40: O
B41: "At least one ingredient item is required" | N41: O | O41: O
A42: Result | B42: Type(N : Normal, A : Abnormal, B : Boundary) | F42: N | G42: B | H42: B | I42: A | J42: B | K42: B | L42: A | M42: A | N42: B | O42: B
...

Sheet CreateMealBatch
A2: Function Code | C2: =Functions!E19 -> CMB | F2: Function Name | L2: =Functions!D19 -> createMealBatch
A3: Created By | C3: LuyenHD | F3: Executed By | L3: LuyenHD
A4: Lines of code | C4: 170 | F4: Lack of test cases | L4: =IF(Functions!E6<>"N/A",SUM(C4*Functions!E6/1000,-O7),"N/A") -> 0
A5: Test requirement
A6: Passed | C6: Failed | F6: Untested | L6: N/A/B | O6: Total Test Cases
A7: =COUNTIF(F63:HS63,"P") -> 17 | C7: =COUNTIF(F63:HS63,"F") -> 0 | F7: =SUM(O7,-A7,-C7) -> 0 | L7: =COUNTIF(E62:HS62,"N") -> 2 | M7: =COUNTIF(E62:HS62,"A") -> 6 | N7: =COUNTIF(E62:HS62,"B") -> 9 | O7: =COUNTA(E9:HV9) -> 17
F9: UTCID01 | G9: UTCID02 | H9: UTCID03 | I9: UTCID04 | J9: UTCID05 | K9: UTCID06 | L9: UTCID07 | M9: UTCID08 | N9: UTCID09 | O9: UTCID10 | P9: UTCID11 | Q9: UTCID12 | R9: UTCID13 | S9: UTCID14 | T9: UTCID15 | U9: UTCID16 | V9: UTCID17
A10: Condition | B10: Precondition
D11: Logged in with the kitchen staff account | F11: O | G11: O | H11: O | I11: O | J11: O | K11: O | L11: O | M11: O | N11: O | O11: O | P11: O | Q11: O | R11: O | S11: O | T11: O | U11: O | V11: O
B12: campaignPhaseId
D13: 745665c5-9891-44a2-acc2-748e032214ce | F13: O | I13: O | J13: O | K13: O | L13: O | M13: O | N13: O | O13: O | P13: O | Q13: O | R13: O | S13: O | T13: O | U13: O | V13: O
D14: "" | G14: O
D15: null | H15: O
B16: plannedMealId
D17: valid-uuid | F17: O | G17: O | H17: O | J17: O | K17: O | L17: O | M17: O | N17: O | O17: O | P17: O | Q17: O | R17: O | S17: O | T17: O | U17: O | V17: O
D18: null | I18: O
B19: foodName
D20: Cơm gà | F20: O | G20: O | H20: O | I20: O | L20: O | M20: O | N20: O | O20: O | P20: O | Q20: O | R20: O | S20: O | T20: O | U20: O | V20: O
D21: "" | J21: O
D22: Ab | K22: O
B23: quantity
D24: 100 | F24: O | G24: O | H24: O | I24: O | J24: O | K24: O | O24: O | P24: O | Q24: O | R24: O | S24: O | T24: O | U24: O | V24: O
D25: 0 | L25: O
D26: -10 | M26: O
D27: 10.5 | N27: O
B28: mediaFileKeys
D29: ["key1", "key2"] | F29: O | G29: O | H29: O | I29: O | J29: O | K29: O | L29: O | M29: O | N29: O | S29: O | T29: O | U29: O | V29: O
D30: [] | O30: O
D31: null | P31: O
D32: ["invalid-key"] | Q32: O
D33: [123, "key1"] | R33: O
B34: ingredientIds
D35: ["id1", "id2"] | F35: O | G35: O | H35: O | I35: O | J35: O | K35: O | L35: O | M35: O | N35: O | O35: O | P35: O | Q35: O | R35: O
D36: [] | S36: O
D37: null | T37: O
D38: ["not-exist-id"] | U38: O
D39: [123, "id1"] | V39: O
A40: Confirm | B40: Return
D41: T | F41: O | I41: O
D42: F | G42: O | H42: O | J42: O | K42: O | L42: O | M42: O | N42: O | O42: O | P42: O | Q42: O | R42: O | S42: O | T42: O | U42: O | V42: O
...

Sheet CreateCampaignCategory
A2: Function Code | C2: =Functions!E20 -> CCC | F2: Function Name | L2: =Functions!D20 -> createCampaignCategory
A3: Created By | C3: LuyenHD | F3: Executed By | L3: LuyenHD
A4: Lines of code | C4: 60 | F4: Lack of test cases | L4: =IF(Functions!E6<>"N/A",SUM(C4*Functions!E6/1000,-O7),"N/A") -> -3
A5: Test requirement
A6: Passed | C6: Failed | F6: Untested | L6: N/A/B | O6: Total Test Cases
A7: =COUNTIF(F39:HS39,"P") -> 9 | C7: =COUNTIF(F39:HS39,"F") -> 0 | F7: =SUM(O7,-A7,-C7) -> 0 | L7: =COUNTIF(E38:N38,"N") -> 1 | M7: =COUNTIF(E38:N38,"A") -> 5 | N7: =COUNTIF(E38:N38,"B") -> 3 | O7: =COUNTA(E9:N9) -> 9
F9: UTCID01 | G9: UTCID02 | H9: UTCID03 | I9: UTCID04 | J9: UTCID05 | K9: UTCID06 | L9: UTCID07 | M9: UTCID08 | N9: UTCID09
A10: Condition | B10: Precondition
D11: Logged in with the admin account | F11: O | G11: O | H11: O | I11: O | J11: O
D12: Logged in with the donor account | K12: O
D13: Logged in with the fundraiser account | L13: O
D14: Logged in with the kitchen staff account | M14: O
D15: Logged in with the delivery staff account | N15: O
D16: Category title already exists | I16: O
B17: title
D18: Hỗ trợ suất ăn | F18: O | H18: O | I18: O | K18: O | L18: O | M18: O | N18: O
D19: "" | G19: O
D20: title length 101 characters | J20: O
B21: description
D22: Xóa đói, hỗ trợ thức ăn | F22: O | G22: O | I22: O | J22: O | K22: O | L22: O | M22: O | N22: O
D23: "" | H23: O
A24: Confirm | B24: Return
D25: T | F25: O
D26: F | G26: O | H26: O | I26: O | J26: O | K26: O | L26: O | M26: O | N26: O
B27: Exception
D28: Throw Validation Error | G28: O | H28: O | J28: O
D29: Throw BadRequestException | I29: O
D30: Throw ForbiddenException | K30: O | L30: O | M30: O | N30: O
B31: Log message
D32: "Create Campaign Category successfully" | F32: O
B33: "Title is required and cannot be empty" | G33: O
B34: "Description is required and cannot be empty" | H34: O
B35: "Category with title ${input.title} already exists" | I35: O
B36: "Title should not be greater than 100 characters" | J36: O
B37: "Only admin can create campaign category" | K37: O | L37: O | M37: O | N37: O
A38: Result | B38: Type(N : Normal, A : Abnormal, B : Boundary) | F38: N | G38: B | H38: B | I38: A | J38: B | K38: A | L38: A | M38: A | N38: A
B39: Passed/Failed | F39: P | G39: P | H39: P | I39: P | J39: P | K39: P | L39: P | M39: P | N39: P
B40: Executed Date | F40: 46005 | G40: 46005 | H40: 46005 | I40: 46005 | J40: 46005 | K40: 46005 | L40: 46005 | M40: 46005 | N40: 46005
B41: Defect ID
